<?xml version="1.0" ?>
<!-- =================================================================================== -->
<!-- |    This document was autogenerated by xacro from robot/khr-3hv_urdf_normal.xacro | -->
<!-- |    EDITING THIS FILE BY HAND IS NOT RECOMMENDED                                 | -->
<!-- =================================================================================== -->
<robot name="khr-3hv" xmlns:xacro="http://ros.org/wiki/xacro">
  <!-- head -->
  <joint name="base_link_to_head" type="revolute">
    <parent link="base_link"/>
    <child link="head"/>
    <origin rpy="0 0 0" xyz="0 0 0.0315"/>
    <axis xyz="0 0 1"/>
    <dynamics damping="0.5"/>
    <limit effort="1.37293" lower="-1.57079637" upper="1.57079637" velocity="0.14"/>
  </joint>
  <link name="head">
    <visual>
      <origin rpy="0 0 0" xyz="0 0 0.017"/>
      <geometry>
        <box size="0.052 0.031 0.033"/>
      </geometry>
      <material name="gray">
        <color rgba="0.8 0.8 0.8 1.0"/>
      </material>
    </visual>
    <collision>
      <origin rpy="0 0 0" xyz="0 0 0.017"/>
      <geometry>
        <box size="0.052 0.031 0.033"/>
      </geometry>
    </collision>
    <inertial>
      <origin rpy="0 0 0" xyz="0 0 0.017"/>
      <mass value="0.1"/>
      <inertia ixx="3.16083333333e-05" ixy="0" ixz="0" iyy="3.05416666667e-05" iyz="0" izz="1.70833333333e-05"/>
    </inertial>
  </link>
  <gazebo reference="head">
    <material>Gazebo/Grey</material>
  </gazebo>
  <!-- base link (body)-->
  <link name="base_link">
    <visual>
      <origin rpy="0 0 0" xyz="0 0 0"/>
      <geometry>
        <box size="0.129 0.105 0.062"/>
      </geometry>
      <material name="gray">
        <color rgba="0.8 0.8 0.8 1.0"/>
      </material>
    </visual>
    <collision>
      <origin rpy="0 0 0" xyz="0 0 0"/>
      <geometry>
        <box size="0.129 0.105 0.062"/>
      </geometry>
    </collision>
    <inertial>
      <origin rpy="0 0 0" xyz="0 0 0"/>
      <mass value="0.3"/>
      <inertia ixx="0.000512125" ixy="0" ixz="0" iyy="0.00069165" iyz="0" izz="0.000371725"/>
    </inertial>
  </link>
  <joint name="base_link_to_body_2" type="revolute">
    <parent link="base_link"/>
    <child link="body_2"/>
    <origin rpy="0 0 0" xyz="0 0 -0.0525"/>
    <axis xyz="0 0 1"/>
    <dynamics damping="0.5"/>
    <limit effort="1.37293" lower="-0.785398185" upper="0.785398185" velocity="0.14"/>
  </joint>
  <link name="body_2">
    <visual>
      <origin rpy="0 0 0" xyz="0 0 0"/>
      <geometry>
        <box size="0.057 0.08 0.041"/>
      </geometry>
      <material name="black">
        <color rgba="0.3 0.3 0.3 1.0"/>
      </material>
    </visual>
    <collision>
      <origin rpy="0 0 0" xyz="0 0 0"/>
      <geometry>
        <box size="0.057 0.08 0.041"/>
      </geometry>
    </collision>
    <inertial>
      <origin rpy="0 0 0" xyz="0 0 0"/>
      <mass value="0.2"/>
      <inertia ixx="8.21666666667e-05" ixy="0" ixz="0" iyy="0.000160816666667" iyz="0" izz="0.000134683333333"/>
    </inertial>
  </link>
  <gazebo reference="base_link">
    <material>Gazebo/Grey</material>
  </gazebo>
  <gazebo reference="body_2">
    <material>Gazebo/Black</material>
  </gazebo>
  <!-- left arm -->
  <joint name="base_link_to_Lshoulder" type="revolute">
    <parent link="base_link"/>
    <child link="Lshoulder"/>
    <origin rpy="0 0 0" xyz="0 0.0525 0.018"/>
    <axis xyz="0 1 0"/>
    <dynamics damping="0.5"/>
    <limit effort="1.37293" lower="-3.14159274" upper="1.04719758" velocity="0.14"/>
  </joint>
  <link name="Lshoulder">
    <visual>
      <origin rpy="0 0 0" xyz="0 0.023 0"/>
      <geometry>
        <box size="0.026 0.026 0.036"/>
      </geometry>
      <material name="black">
        <color rgba="0.3 0.3 0.3 1.0"/>
      </material>
    </visual>
    <collision>
      <origin rpy="0 0 0" xyz="0 0.023 0"/>
      <geometry>
        <box size="0.026 0.026 0.036"/>
      </geometry>
    </collision>
    <inertial>
      <origin rpy="0 0 0" xyz="0 0.023 0"/>
      <mass value="0.0625"/>
      <inertia ixx="1.02708333333e-05" ixy="0" ixz="0" iyy="7.04166666667e-06" iyz="0" izz="1.02708333333e-05"/>
    </inertial>
  </link>
  <joint name="Lshoulder_to_Lupper_arm" type="revolute">
    <parent link="Lshoulder"/>
    <child link="Lupper_arm"/>
    <origin rpy="0 0 0" xyz="0 0.023 0"/>
    <axis xyz="1 0 0"/>
    <dynamics damping="0.5"/>
    <limit effort="1.37293" lower="-0.0" upper="1.57079637" velocity="0.14"/>
  </joint>
  <link name="Lupper_arm">
    <visual>
      <origin rpy="0 0 0" xyz="0 0 -0.079"/>
      <geometry>
        <box size="0.026 0.026 0.082"/>
      </geometry>
      <material name="black">
        <color rgba="0.3 0.3 0.3 1.0"/>
      </material>
    </visual>
    <collision>
      <origin rpy="0 0 0" xyz="0 0 -0.079"/>
      <geometry>
        <box size="0.026 0.026 0.082"/>
      </geometry>
    </collision>
    <inertial>
      <origin rpy="0 0 0" xyz="0 0 -0.079"/>
      <mass value="0.0625"/>
      <inertia ixx="3.85416666667e-05" ixy="0" ixz="0" iyy="7.04166666667e-06" iyz="0" izz="3.85416666667e-05"/>
    </inertial>
  </link>
  <joint name="Lupper_arm_to_Llower_arm" type="revolute">
    <parent link="Lupper_arm"/>
    <child link="Llower_arm"/>
    <origin rpy="0 0 0" xyz="0.013 0 -0.125"/>
    <axis xyz="0 1 0"/>
    <dynamics damping="0.5"/>
    <limit effort="1.37293" lower="-2.61799395" upper="0.0" velocity="0.14"/>
  </joint>
  <link name="Llower_arm">
    <visual>
      <origin rpy="0 0 0" xyz="-0.013 0 -0.033"/>
      <geometry>
        <box size="0.026 0.026 0.056"/>
      </geometry>
      <material name="black">
        <color rgba="0.3 0.3 0.3 1.0"/>
      </material>
    </visual>
    <collision>
      <origin rpy="0 0 0" xyz="-0.013 0 -0.033"/>
      <geometry>
        <box size="0.026 0.026 0.056"/>
      </geometry>
    </collision>
    <inertial>
      <origin rpy="0 0 0" xyz="-0.013 0 -0.033"/>
      <mass value="0.025"/>
      <inertia ixx="7.94166666667e-06" ixy="0" ixz="0" iyy="2.81666666667e-06" iyz="0" izz="7.94166666667e-06"/>
    </inertial>
  </link>
  <gazebo reference="Lshoulder">
    <material>Gazebo/Black</material>
  </gazebo>
  <gazebo reference="Lupper_arm">
    <material>Gazebo/Black</material>
  </gazebo>
  <gazebo reference="Llower_arm">
    <material>Gazebo/Black</material>
  </gazebo>
  <!-- right arm -->
  <joint name="base_link_to_Rshoulder" type="revolute">
    <parent link="base_link"/>
    <child link="Rshoulder"/>
    <origin rpy="0 0 0" xyz="0 -0.0525 0.018"/>
    <axis xyz="0 1 0"/>
    <dynamics damping="0.5"/>
    <limit effort="1.37293" lower="-3.14159274" upper="1.04719758" velocity="0.14"/>
  </joint>
  <link name="Rshoulder">
    <visual>
      <origin rpy="0 0 0" xyz="0 -0.023 0"/>
      <geometry>
        <box size="0.026 0.026 0.036"/>
      </geometry>
      <material name="black">
        <color rgba="0.3 0.3 0.3 1.0"/>
      </material>
    </visual>
    <collision>
      <origin rpy="0 0 0" xyz="0 -0.023 0"/>
      <geometry>
        <box size="0.026 0.026 0.036"/>
      </geometry>
    </collision>
    <inertial>
      <origin rpy="0 0 0" xyz="0 -0.023 0"/>
      <mass value="0.0625"/>
      <inertia ixx="1.02708333333e-05" ixy="0" ixz="0" iyy="7.04166666667e-06" iyz="0" izz="1.02708333333e-05"/>
    </inertial>
  </link>
  <joint name="Rshoulder_to_Rupper_arm" type="revolute">
    <parent link="Rshoulder"/>
    <child link="Rupper_arm"/>
    <origin rpy="0 0 0" xyz="0 -0.023 0"/>
    <axis xyz="1 0 0"/>
    <dynamics damping="0.5"/>
    <limit effort="1.37293" lower="-1.57079637" upper="0.0" velocity="0.14"/>
  </joint>
  <link name="Rupper_arm">
    <visual>
      <origin rpy="0 0 0" xyz="0 0 -0.079"/>
      <geometry>
        <box size="0.026 0.026 0.082"/>
      </geometry>
      <material name="black">
        <color rgba="0.3 0.3 0.3 1.0"/>
      </material>
    </visual>
    <collision>
      <origin rpy="0 0 0" xyz="0 0 -0.079"/>
      <geometry>
        <box size="0.026 0.026 0.082"/>
      </geometry>
    </collision>
    <inertial>
      <origin rpy="0 0 0" xyz="0 0 -0.079"/>
      <mass value="0.0625"/>
      <inertia ixx="3.85416666667e-05" ixy="0" ixz="0" iyy="7.04166666667e-06" iyz="0" izz="3.85416666667e-05"/>
    </inertial>
  </link>
  <joint name="Rupper_arm_to_Rlower_arm" type="revolute">
    <parent link="Rupper_arm"/>
    <child link="Rlower_arm"/>
    <origin rpy="0 0 0" xyz="0.013 0 -0.125"/>
    <axis xyz="0 1 0"/>
    <dynamics damping="0.5"/>
    <limit effort="1.37293" lower="-2.61799395" upper="0.0" velocity="0.14"/>
  </joint>
  <link name="Rlower_arm">
    <visual>
      <origin rpy="0 0 0" xyz="-0.013 0 -0.033"/>
      <geometry>
        <box size="0.026 0.026 0.056"/>
      </geometry>
      <material name="black">
        <color rgba="0.3 0.3 0.3 1.0"/>
      </material>
    </visual>
    <collision>
      <origin rpy="0 0 0" xyz="-0.013 0 -0.033"/>
      <geometry>
        <box size="0.026 0.026 0.056"/>
      </geometry>
    </collision>
    <inertial>
      <origin rpy="0 0 0" xyz="-0.013 0 -0.033"/>
      <mass value="0.025"/>
      <inertia ixx="7.94166666667e-06" ixy="0" ixz="0" iyy="2.81666666667e-06" iyz="0" izz="7.94166666667e-06"/>
    </inertial>
  </link>
  <gazebo reference="Rshoulder">
    <material>Gazebo/Black</material>
  </gazebo>
  <gazebo reference="Rupper_arm">
    <material>Gazebo/Black</material>
  </gazebo>
  <gazebo reference="Rlower_arm">
    <material>Gazebo/Black</material>
  </gazebo>
  <!-- left leg -->
  <joint name="body_2_to_Lhips" type="revolute">
    <parent link="body_2"/>
    <child link="Lhips"/>
    <origin rpy="0 0 0" xyz="0 0.03 -0.0255"/>
    <axis xyz="0 0 1"/>
    <dynamics damping="0.5"/>
    <limit effort="1.37293" lower="-0.52359879" upper="0.785398185" velocity="0.14"/>
  </joint>
  <link name="Lhips">
    <visual>
      <origin rpy="0 0 0" xyz="0 0 0"/>
      <geometry>
        <box size="0.03 0.03 0.0039"/>
      </geometry>
      <material name="black">
        <color rgba="0.3 0.3 0.3 1.0"/>
      </material>
    </visual>
    <collision>
      <origin rpy="0 0 0" xyz="0 0 0"/>
      <geometry>
        <box size="0.03 0.03 0.0039"/>
      </geometry>
    </collision>
    <inertial>
      <origin rpy="0 0 0" xyz="0 0 0"/>
      <mass value="0.048"/>
      <inertia ixx="3.66084e-06" ixy="0" ixz="0" iyy="7.2e-06" iyz="0" izz="3.66084e-06"/>
    </inertial>
  </link>
  <joint name="Lhips_to_Lthigh" type="revolute">
    <parent link="Lhips"/>
    <child link="Lthigh"/>
    <origin rpy="0 0 0" xyz="0 0 -0.030"/>
    <axis xyz="1 0 0"/>
    <dynamics damping="0.5"/>
    <limit effort="1.37293" lower="-0.52359879" upper="0.785398185" velocity="0.14"/>
  </joint>
  <link name="Lthigh">
    <visual>
      <origin rpy="0 0 0" xyz="0 0 0"/>
      <geometry>
        <box size="0.03 0.03 0.026"/>
      </geometry>
      <material name="black">
        <color rgba="0.3 0.3 0.3 1.0"/>
      </material>
    </visual>
    <collision>
      <origin rpy="0 0 0" xyz="0 0 0"/>
      <geometry>
        <box size="0.03 0.03 0.026"/>
      </geometry>
    </collision>
    <inertial>
      <origin rpy="0 0 0" xyz="0 0 0"/>
      <mass value="0.068"/>
      <inertia ixx="8.93066666667e-06" ixy="0" ixz="0" iyy="1.02e-05" iyz="0" izz="8.93066666667e-06"/>
    </inertial>
  </link>
  <joint name="Lthigh_to_Lknee" type="revolute">
    <parent link="Lthigh"/>
    <child link="Lknee"/>
    <origin rpy="0 0 0" xyz="0 0 -0.046"/>
    <axis xyz="0 1 0"/>
    <dynamics damping="0.5"/>
    <limit effort="1.37293" lower="-2.09439516" upper="0.785398185" velocity="0.14"/>
  </joint>
  <link name="Lknee">
    <visual>
      <origin rpy="0 0 0" xyz="0 0 -0.034"/>
      <geometry>
        <box size="0.03 0.03 0.088"/>
      </geometry>
      <material name="black">
        <color rgba="0.3 0.3 0.3 1.0"/>
      </material>
    </visual>
    <collision>
      <origin rpy="0 0 0" xyz="0 0 -0.034"/>
      <geometry>
        <box size="0.03 0.03 0.088"/>
      </geometry>
    </collision>
    <inertial>
      <origin rpy="0 0 0" xyz="0 0 -0.034"/>
      <mass value="0.118"/>
      <inertia ixx="8.49993333333e-05" ixy="0" ixz="0" iyy="1.77e-05" iyz="0" izz="8.49993333333e-05"/>
    </inertial>
  </link>
  <joint name="Lknee_to_Lshin" type="revolute">
    <parent link="Lknee"/>
    <child link="Lshin"/>
    <origin rpy="0 0 0" xyz="-0.0205 0 -0.0885"/>
    <axis xyz="0 1 0"/>
    <dynamics damping="0.5"/>
    <limit effort="1.37293" lower="-0.0" upper="2.61799395" velocity="0.14"/>
  </joint>
  <link name="Lshin">
    <visual>
      <origin rpy="0 0 0" xyz="0.0205 0 -0.024"/>
      <geometry>
        <box size="0.03 0.03 0.047"/>
      </geometry>
      <material name="black">
        <color rgba="0.3 0.3 0.3 1.0"/>
      </material>
    </visual>
    <collision>
      <origin rpy="0 0 0" xyz="0.0205 0 -0.024"/>
      <geometry>
        <box size="0.03 0.03 0.047"/>
      </geometry>
    </collision>
    <inertial>
      <origin rpy="0 0 0" xyz="0.0205 0 -0.024"/>
      <mass value="0.068"/>
      <inertia ixx="1.76176666667e-05" ixy="0" ixz="0" iyy="1.02e-05" iyz="0" izz="1.76176666667e-05"/>
    </inertial>
  </link>
  <joint name="Lshin_to_Lankle" type="revolute">
    <parent link="Lshin"/>
    <child link="Lankle"/>
    <origin rpy="0 0 0" xyz="0.0205 0 -0.0319"/>
    <axis xyz="0 1 0"/>
    <dynamics damping="0.5"/>
    <limit effort="1.37293" lower="-1.57079637" upper="1.04719758" velocity="0.14"/>
  </joint>
  <link name="Lankle">
    <visual>
      <origin rpy="0 0 0" xyz="0 0 -0.037"/>
      <geometry>
        <box size="0.03 0.03 0.02"/>
      </geometry>
      <material name="black">
        <color rgba="0.3 0.3 0.3 1.0"/>
      </material>
    </visual>
    <collision>
      <origin rpy="0 0 0" xyz="0 0 -0.037"/>
      <geometry>
        <box size="0.03 0.03 0.02"/>
      </geometry>
    </collision>
    <inertial>
      <origin rpy="0 0 0" xyz="0 0 -0.037"/>
      <mass value="0.068"/>
      <inertia ixx="7.36666666667e-06" ixy="0" ixz="0" iyy="1.02e-05" iyz="0" izz="7.36666666667e-06"/>
    </inertial>
  </link>
  <joint name="Lankle_to_Lfoot" type="revolute">
    <parent link="Lankle"/>
    <child link="Lfoot"/>
    <origin rpy="0 0 0" xyz="0 0 -0.037"/>
    <axis xyz="1 0 0"/>
    <dynamics damping="0.5"/>
    <limit effort="1.37293" lower="-0.785398185" upper="0.785398185" velocity="0.14"/>
  </joint>
  <link name="Lfoot">
    <visual>
      <origin rpy="0 0 0" xyz="0 0.015 -0.0315"/>
      <geometry>
        <box size="0.122 0.078 0.01"/>
      </geometry>
      <material name="black">
        <color rgba="0.3 0.3 0.3 1.0"/>
      </material>
    </visual>
    <collision>
      <origin rpy="0 0 0" xyz="0 0.015 -0.0315"/>
      <geometry>
        <box size="0.122 0.078 0.01"/>
      </geometry>
    </collision>
    <inertial>
      <origin rpy="0 0 0" xyz="0 0.015 -0.0315"/>
      <mass value="0.03"/>
      <inertia ixx="3.746e-05" ixy="0" ixz="0" iyy="5.242e-05" iyz="0" izz="1.546e-05"/>
    </inertial>
  </link>
  <!-- set force sensor -->
  <joint name="Lfsensor1_joint" type="fixed">
    <origin rpy="0 0 0" xyz="0.046  0.039 -0.0415"/>
    <parent link="Lfoot"/>
    <child link="Lfsensor1"/>
  </joint>
  <link name="Lfsensor1">
    <visual>
      <origin rpy="0 0 0" xyz="0 0 0"/>
      <geometry>
        <box size="0.02 0.02 0.01"/>
      </geometry>
      <material name="red">
        <color rgba="1.0 0.0 0.0 1.0"/>
      </material>
    </visual>
    <collision>
      <origin rpy="0 0 0" xyz="0 0 0"/>
      <geometry>
        <box size="0.02 0.02 0.01"/>
      </geometry>
    </collision>
    <inertial>
      <origin rpy="0 0 0" xyz="0 0 0"/>
      <mass value="0.005"/>
      <inertia ixx="2.08333333333e-07" ixy="0" ixz="0" iyy="3.33333333333e-07" iyz="0" izz="2.08333333333e-07"/>
    </inertial>
  </link>
  <sensor name="Lfsensor1_sensor" update_rate="20">
    <origin rpy="0 0 0" xyz="0.046  0.039 -0.0415"/>
    <parent link="Lfoot"/>
  </sensor>
  <gazebo reference="Lfsensor1">
    <material>Gazebo/Red</material>
  </gazebo>
  <joint name="Lfsensor2_joint" type="fixed">
    <origin rpy="0 0 0" xyz="-0.046  0.039 -0.0415"/>
    <parent link="Lfoot"/>
    <child link="Lfsensor2"/>
  </joint>
  <link name="Lfsensor2">
    <visual>
      <origin rpy="0 0 0" xyz="0 0 0"/>
      <geometry>
        <box size="0.02 0.02 0.01"/>
      </geometry>
      <material name="red">
        <color rgba="1.0 0.0 0.0 1.0"/>
      </material>
    </visual>
    <collision>
      <origin rpy="0 0 0" xyz="0 0 0"/>
      <geometry>
        <box size="0.02 0.02 0.01"/>
      </geometry>
    </collision>
    <inertial>
      <origin rpy="0 0 0" xyz="0 0 0"/>
      <mass value="0.005"/>
      <inertia ixx="2.08333333333e-07" ixy="0" ixz="0" iyy="3.33333333333e-07" iyz="0" izz="2.08333333333e-07"/>
    </inertial>
  </link>
  <sensor name="Lfsensor2_sensor" update_rate="20">
    <origin rpy="0 0 0" xyz="-0.046  0.039 -0.0415"/>
    <parent link="Lfoot"/>
  </sensor>
  <gazebo reference="Lfsensor2">
    <material>Gazebo/Red</material>
  </gazebo>
  <joint name="Lfsensor3_joint" type="fixed">
    <origin rpy="0 0 0" xyz="0.046  -0.009 -0.0415"/>
    <parent link="Lfoot"/>
    <child link="Lfsensor3"/>
  </joint>
  <link name="Lfsensor3">
    <visual>
      <origin rpy="0 0 0" xyz="0 0 0"/>
      <geometry>
        <box size="0.02 0.02 0.01"/>
      </geometry>
      <material name="red">
        <color rgba="1.0 0.0 0.0 1.0"/>
      </material>
    </visual>
    <collision>
      <origin rpy="0 0 0" xyz="0 0 0"/>
      <geometry>
        <box size="0.02 0.02 0.01"/>
      </geometry>
    </collision>
    <inertial>
      <origin rpy="0 0 0" xyz="0 0 0"/>
      <mass value="0.005"/>
      <inertia ixx="2.08333333333e-07" ixy="0" ixz="0" iyy="3.33333333333e-07" iyz="0" izz="2.08333333333e-07"/>
    </inertial>
  </link>
  <sensor name="Lfsensor3_sensor" update_rate="20">
    <origin rpy="0 0 0" xyz="0.046  -0.009 -0.0415"/>
    <parent link="Lfoot"/>
  </sensor>
  <gazebo reference="Lfsensor3">
    <material>Gazebo/Red</material>
  </gazebo>
  <joint name="Lfsensor4_joint" type="fixed">
    <origin rpy="0 0 0" xyz="-0.046  -0.009 -0.0415"/>
    <parent link="Lfoot"/>
    <child link="Lfsensor4"/>
  </joint>
  <link name="Lfsensor4">
    <visual>
      <origin rpy="0 0 0" xyz="0 0 0"/>
      <geometry>
        <box size="0.02 0.02 0.01"/>
      </geometry>
      <material name="red">
        <color rgba="1.0 0.0 0.0 1.0"/>
      </material>
    </visual>
    <collision>
      <origin rpy="0 0 0" xyz="0 0 0"/>
      <geometry>
        <box size="0.02 0.02 0.01"/>
      </geometry>
    </collision>
    <inertial>
      <origin rpy="0 0 0" xyz="0 0 0"/>
      <mass value="0.005"/>
      <inertia ixx="2.08333333333e-07" ixy="0" ixz="0" iyy="3.33333333333e-07" iyz="0" izz="2.08333333333e-07"/>
    </inertial>
  </link>
  <sensor name="Lfsensor4_sensor" update_rate="20">
    <origin rpy="0 0 0" xyz="-0.046  -0.009 -0.0415"/>
    <parent link="Lfoot"/>
  </sensor>
  <gazebo reference="Lfsensor4">
    <material>Gazebo/Red</material>
  </gazebo>
  <joint name="Lfoot_to_Lfoot2" type="fixed">
    <parent link="Lfoot"/>
    <child link="Lfoot2"/>
    <origin rpy="0 0 0" xyz="0 0.015 -0.0475"/>
  </joint>
  <link name="Lfoot2">
    <visual>
      <origin rpy="0 0 0" xyz="0 0 0"/>
      <geometry>
        <box size="0.122 0.078 0.002"/>
      </geometry>
      <material name="gray">
        <color rgba="0.8 0.8 0.8 1.0"/>
      </material>
    </visual>
    <collision>
      <origin rpy="0 0 0" xyz="0 0 0"/>
      <geometry>
        <box size="0.122 0.078 0.002"/>
      </geometry>
    </collision>
    <inertial>
      <origin rpy="0 0 0" xyz="0 0 0"/>
      <mass value="0.05"/>
      <inertia ixx="6.20333333333e-05" ixy="0" ixz="0" iyy="8.73666666667e-05" iyz="0" izz="2.53666666667e-05"/>
    </inertial>
  </link>
  <gazebo reference="Lhips">
    <material>Gazebo/Black</material>
  </gazebo>
  <gazebo reference="Lthigh">
    <material>Gazebo/Black</material>
  </gazebo>
  <gazebo reference="Lknee">
    <material>Gazebo/Black</material>
  </gazebo>
  <gazebo reference="Lshin">
    <material>Gazebo/Black</material>
  </gazebo>
  <gazebo reference="Lankle">
    <material>Gazebo/Black</material>
  </gazebo>
  <gazebo reference="Lfoot">
    <material>Gazebo/Black</material>
  </gazebo>
  <gazebo reference="Lfoot2">
    <material>Gazebo/Grey</material>
  </gazebo>
  <!-- right leg -->
  <joint name="body_2_to_Rhips" type="revolute">
    <parent link="body_2"/>
    <child link="Rhips"/>
    <origin rpy="0 0 0" xyz="0 -0.03 -0.0255"/>
    <axis xyz="0 0 1"/>
    <dynamics damping="0.5"/>
    <limit effort="1.37293" lower="-0.785398185" upper="0.52359879" velocity="0.14"/>
  </joint>
  <link name="Rhips">
    <visual>
      <origin rpy="0 0 0" xyz="0 0 0"/>
      <geometry>
        <box size="0.03 0.03 0.0039"/>
      </geometry>
      <material name="black">
        <color rgba="0.3 0.3 0.3 1.0"/>
      </material>
    </visual>
    <collision>
      <origin rpy="0 0 0" xyz="0 0 0"/>
      <geometry>
        <box size="0.03 0.03 0.0039"/>
      </geometry>
    </collision>
    <inertial>
      <origin rpy="0 0 0" xyz="0 0 0"/>
      <mass value="0.048"/>
      <inertia ixx="3.66084e-06" ixy="0" ixz="0" iyy="7.2e-06" iyz="0" izz="3.66084e-06"/>
    </inertial>
  </link>
  <joint name="Rhips_to_Rthigh" type="revolute">
    <parent link="Rhips"/>
    <child link="Rthigh"/>
    <origin rpy="0 0 0" xyz="0 0 -0.030"/>
    <axis xyz="1 0 0"/>
    <dynamics damping="0.5"/>
    <limit effort="1.37293" lower="-0.785398185" upper="0.52359879" velocity="0.14"/>
  </joint>
  <link name="Rthigh">
    <visual>
      <origin rpy="0 0 0" xyz="0 0 0"/>
      <geometry>
        <box size="0.03 0.03 0.026"/>
      </geometry>
      <material name="black">
        <color rgba="0.3 0.3 0.3 1.0"/>
      </material>
    </visual>
    <collision>
      <origin rpy="0 0 0" xyz="0 0 0"/>
      <geometry>
        <box size="0.03 0.03 0.026"/>
      </geometry>
    </collision>
    <inertial>
      <origin rpy="0 0 0" xyz="0 0 0"/>
      <mass value="0.068"/>
      <inertia ixx="8.93066666667e-06" ixy="0" ixz="0" iyy="1.02e-05" iyz="0" izz="8.93066666667e-06"/>
    </inertial>
  </link>
  <joint name="Rthigh_to_Rknee" type="revolute">
    <parent link="Rthigh"/>
    <child link="Rknee"/>
    <origin rpy="0 0 0" xyz="0 0 -0.046"/>
    <axis xyz="0 1 0"/>
    <dynamics damping="0.5"/>
    <limit effort="1.37293" lower="-2.09439516" upper="0.785398185" velocity="0.14"/>
  </joint>
  <link name="Rknee">
    <visual>
      <origin rpy="0 0 0" xyz="0 0 -0.034"/>
      <geometry>
        <box size="0.03 0.03 0.088"/>
      </geometry>
      <material name="black">
        <color rgba="0.3 0.3 0.3 1.0"/>
      </material>
    </visual>
    <collision>
      <origin rpy="0 0 0" xyz="0 0 -0.034"/>
      <geometry>
        <box size="0.03 0.03 0.088"/>
      </geometry>
    </collision>
    <inertial>
      <origin rpy="0 0 0" xyz="0 0 -0.034"/>
      <mass value="0.118"/>
      <inertia ixx="8.49993333333e-05" ixy="0" ixz="0" iyy="1.77e-05" iyz="0" izz="8.49993333333e-05"/>
    </inertial>
  </link>
  <joint name="Rknee_to_Rshin" type="revolute">
    <parent link="Rknee"/>
    <child link="Rshin"/>
    <origin rpy="0 0 0" xyz="-0.0205 0 -0.0885"/>
    <axis xyz="0 1 0"/>
    <dynamics damping="0.5"/>
    <limit effort="1.37293" lower="-0.0" upper="2.61799395" velocity="0.14"/>
  </joint>
  <link name="Rshin">
    <visual>
      <origin rpy="0 0 0" xyz="0.0205 0 -0.024"/>
      <geometry>
        <box size="0.03 0.03 0.047"/>
      </geometry>
      <material name="black">
        <color rgba="0.3 0.3 0.3 1.0"/>
      </material>
    </visual>
    <collision>
      <origin rpy="0 0 0" xyz="0.0205 0 -0.024"/>
      <geometry>
        <box size="0.03 0.03 0.047"/>
      </geometry>
    </collision>
    <inertial>
      <origin rpy="0 0 0" xyz="0.0205 0 -0.024"/>
      <mass value="0.068"/>
      <inertia ixx="1.76176666667e-05" ixy="0" ixz="0" iyy="1.02e-05" iyz="0" izz="1.76176666667e-05"/>
    </inertial>
  </link>
  <joint name="Rshin_to_Rankle" type="revolute">
    <parent link="Rshin"/>
    <child link="Rankle"/>
    <origin rpy="0 0 0" xyz="0.0205 0 -0.0319"/>
    <axis xyz="0 1 0"/>
    <dynamics damping="0.5"/>
    <limit effort="1.37293" lower="-1.57079637" upper="1.04719758" velocity="0.14"/>
  </joint>
  <link name="Rankle">
    <visual>
      <origin rpy="0 0 0" xyz="0 0 -0.037"/>
      <geometry>
        <box size="0.03 0.03 0.02"/>
      </geometry>
      <material name="black">
        <color rgba="0.3 0.3 0.3 1.0"/>
      </material>
    </visual>
    <collision>
      <origin rpy="0 0 0" xyz="0 0 -0.037"/>
      <geometry>
        <box size="0.03 0.03 0.02"/>
      </geometry>
    </collision>
    <inertial>
      <origin rpy="0 0 0" xyz="0 0 -0.037"/>
      <mass value="0.068"/>
      <inertia ixx="7.36666666667e-06" ixy="0" ixz="0" iyy="1.02e-05" iyz="0" izz="7.36666666667e-06"/>
    </inertial>
  </link>
  <joint name="Rankle_to_Rfoot" type="revolute">
    <parent link="Rankle"/>
    <child link="Rfoot"/>
    <origin rpy="0 0 0" xyz="0 0 -0.037"/>
    <axis xyz="1 0 0"/>
    <dynamics damping="0.5"/>
    <limit effort="1.37293" lower="-0.785398185" upper="0.785398185" velocity="0.14"/>
  </joint>
  <link name="Rfoot">
    <visual>
      <origin rpy="0 0 0" xyz="0 -0.015 -0.0315"/>
      <geometry>
        <box size="0.122 0.078 0.01"/>
      </geometry>
      <material name="black">
        <color rgba="0.3 0.3 0.3 1.0"/>
      </material>
    </visual>
    <collision>
      <origin rpy="0 0 0" xyz="0 -0.015 -0.0315"/>
      <geometry>
        <box size="0.122 0.078 0.01"/>
      </geometry>
    </collision>
    <inertial>
      <origin rpy="0 0 0" xyz="0 -0.015 -0.0315"/>
      <mass value="0.03"/>
      <inertia ixx="3.746e-05" ixy="0" ixz="0" iyy="5.242e-05" iyz="0" izz="1.546e-05"/>
    </inertial>
  </link>
  <!-- set force sensor -->
  <joint name="Rfsensor1_joint" type="fixed">
    <origin rpy="0 0 0" xyz="0.046  0.009 -0.0415"/>
    <parent link="Rfoot"/>
    <child link="Rfsensor1"/>
  </joint>
  <link name="Rfsensor1">
    <visual>
      <origin rpy="0 0 0" xyz="0 0 0"/>
      <geometry>
        <box size="0.02 0.02 0.01"/>
      </geometry>
      <material name="red">
        <color rgba="1.0 0.0 0.0 1.0"/>
      </material>
    </visual>
    <collision>
      <origin rpy="0 0 0" xyz="0 0 0"/>
      <geometry>
        <box size="0.02 0.02 0.01"/>
      </geometry>
    </collision>
    <inertial>
      <origin rpy="0 0 0" xyz="0 0 0"/>
      <mass value="0.005"/>
      <inertia ixx="2.08333333333e-07" ixy="0" ixz="0" iyy="3.33333333333e-07" iyz="0" izz="2.08333333333e-07"/>
    </inertial>
  </link>
  <sensor name="Rfsensor1_sensor" update_rate="20">
    <origin rpy="0 0 0" xyz="0.046  0.009 -0.0415"/>
    <parent link="Rfoot"/>
  </sensor>
  <gazebo reference="Rfsensor1">
    <material>Gazebo/Red</material>
  </gazebo>
  <joint name="Rfsensor2_joint" type="fixed">
    <origin rpy="0 0 0" xyz="-0.046  0.009 -0.0415"/>
    <parent link="Rfoot"/>
    <child link="Rfsensor2"/>
  </joint>
  <link name="Rfsensor2">
    <visual>
      <origin rpy="0 0 0" xyz="0 0 0"/>
      <geometry>
        <box size="0.02 0.02 0.01"/>
      </geometry>
      <material name="red">
        <color rgba="1.0 0.0 0.0 1.0"/>
      </material>
    </visual>
    <collision>
      <origin rpy="0 0 0" xyz="0 0 0"/>
      <geometry>
        <box size="0.02 0.02 0.01"/>
      </geometry>
    </collision>
    <inertial>
      <origin rpy="0 0 0" xyz="0 0 0"/>
      <mass value="0.005"/>
      <inertia ixx="2.08333333333e-07" ixy="0" ixz="0" iyy="3.33333333333e-07" iyz="0" izz="2.08333333333e-07"/>
    </inertial>
  </link>
  <sensor name="Rfsensor2_sensor" update_rate="20">
    <origin rpy="0 0 0" xyz="-0.046  0.009 -0.0415"/>
    <parent link="Rfoot"/>
  </sensor>
  <gazebo reference="Rfsensor2">
    <material>Gazebo/Red</material>
  </gazebo>
  <joint name="Rfsensor3_joint" type="fixed">
    <origin rpy="0 0 0" xyz="0.046  -0.039 -0.0415"/>
    <parent link="Rfoot"/>
    <child link="Rfsensor3"/>
  </joint>
  <link name="Rfsensor3">
    <visual>
      <origin rpy="0 0 0" xyz="0 0 0"/>
      <geometry>
        <box size="0.02 0.02 0.01"/>
      </geometry>
      <material name="red">
        <color rgba="1.0 0.0 0.0 1.0"/>
      </material>
    </visual>
    <collision>
      <origin rpy="0 0 0" xyz="0 0 0"/>
      <geometry>
        <box size="0.02 0.02 0.01"/>
      </geometry>
    </collision>
    <inertial>
      <origin rpy="0 0 0" xyz="0 0 0"/>
      <mass value="0.005"/>
      <inertia ixx="2.08333333333e-07" ixy="0" ixz="0" iyy="3.33333333333e-07" iyz="0" izz="2.08333333333e-07"/>
    </inertial>
  </link>
  <sensor name="Rfsensor3_sensor" update_rate="20">
    <origin rpy="0 0 0" xyz="0.046  -0.039 -0.0415"/>
    <parent link="Rfoot"/>
  </sensor>
  <gazebo reference="Rfsensor3">
    <material>Gazebo/Red</material>
  </gazebo>
  <joint name="Rfsensor4_joint" type="fixed">
    <origin rpy="0 0 0" xyz="-0.046  -0.039 -0.0415"/>
    <parent link="Rfoot"/>
    <child link="Rfsensor4"/>
  </joint>
  <link name="Rfsensor4">
    <visual>
      <origin rpy="0 0 0" xyz="0 0 0"/>
      <geometry>
        <box size="0.02 0.02 0.01"/>
      </geometry>
      <material name="red">
        <color rgba="1.0 0.0 0.0 1.0"/>
      </material>
    </visual>
    <collision>
      <origin rpy="0 0 0" xyz="0 0 0"/>
      <geometry>
        <box size="0.02 0.02 0.01"/>
      </geometry>
    </collision>
    <inertial>
      <origin rpy="0 0 0" xyz="0 0 0"/>
      <mass value="0.005"/>
      <inertia ixx="2.08333333333e-07" ixy="0" ixz="0" iyy="3.33333333333e-07" iyz="0" izz="2.08333333333e-07"/>
    </inertial>
  </link>
  <sensor name="Rfsensor4_sensor" update_rate="20">
    <origin rpy="0 0 0" xyz="-0.046  -0.039 -0.0415"/>
    <parent link="Rfoot"/>
  </sensor>
  <gazebo reference="Rfsensor4">
    <material>Gazebo/Red</material>
  </gazebo>
  <joint name="Rfoot_to_Rfoot2" type="fixed">
    <parent link="Rfoot"/>
    <child link="Rfoot2"/>
    <origin rpy="0 0 0" xyz="0 -0.015 -0.0475"/>
  </joint>
  <link name="Rfoot2">
    <visual>
      <origin rpy="0 0 0" xyz="0 0 0"/>
      <geometry>
        <box size="0.122 0.078 0.002"/>
      </geometry>
      <material name="gray">
        <color rgba="0.8 0.8 0.8 1.0"/>
      </material>
    </visual>
    <collision>
      <origin rpy="0 0 0" xyz="0 0 0"/>
      <geometry>
        <box size="0.122 0.078 0.002"/>
      </geometry>
    </collision>
    <inertial>
      <origin rpy="0 0 0" xyz="0 0 0"/>
      <mass value="0.05"/>
      <inertia ixx="6.20333333333e-05" ixy="0" ixz="0" iyy="8.73666666667e-05" iyz="0" izz="2.53666666667e-05"/>
    </inertial>
  </link>
  <gazebo reference="Rhips">
    <material>Gazebo/Black</material>
  </gazebo>
  <gazebo reference="Rthigh">
    <material>Gazebo/Black</material>
  </gazebo>
  <gazebo reference="Rknee">
    <material>Gazebo/Black</material>
  </gazebo>
  <gazebo reference="Rshin">
    <material>Gazebo/Black</material>
  </gazebo>
  <gazebo reference="Rankle">
    <material>Gazebo/Black</material>
  </gazebo>
  <gazebo reference="Rfoot">
    <material>Gazebo/Black</material>
  </gazebo>
  <gazebo reference="Rfoot2">
    <material>Gazebo/Grey</material>
  </gazebo>
</robot>

