<<<<<<< HEAD
<?xml version="1.0" ?>
<!-- =================================================================================== -->
<!-- |    This document was autogenerated by xacro from khr-3hv_urdf.xacro             | -->
<!-- |    EDITING THIS FILE BY HAND IS NOT RECOMMENDED                                 | -->
<!-- =================================================================================== -->
<robot name="khr-3hv" xmlns:xacro="http://ros.org/wiki/xacro">
  <!-- ros_control plugin -->
  <!-- common color -->
  <!-- calculate box inertia -->
  <!-- ros_control plugin -->
  <!-- common color -->
  <!-- calculate box inertia -->
  <!-- ros_control plugin -->
  <!-- common color -->
  <!-- calculate box inertia -->
  <!-- ros_control plugin -->
  <!-- common color -->
  <!-- calculate box inertia -->
  <!-- ros_control plugin -->
  <!-- common color -->
  <!-- calculate box inertia -->
  <!-- ros_control plugin -->
  <!-- ros_control plugin -->
  <gazebo>
    <plugin filename="libgazebo_ros_control.so" name="gazebo_ros_control">
      <robotNamespace>/khr-3hv</robotNamespace>
      <robotSimType>gazebo_ros_control/DefaultRobotHWSim</robotSimType>
    </plugin>
  </gazebo>
  <!-- head -->
  <joint name="base_link_to_head" type="revolute">
    <parent link="base_link"/>
    <child link="head"/>
    <origin rpy="0 0 0" xyz="0 0 0.0315"/>
    <axis xyz="0 0 1"/>
    <dynamics damping="0.5"/>
    <limit effort="0.5" lower="-1.57079637" upper="1.57079637" velocity="6.0"/>
  </joint>
  <link name="head">
    <visual>
      <origin rpy="0 0 0" xyz="0 0 0.017"/>
      <geometry>
        <box size="0.052 0.031 0.033"/>
      </geometry>
      <material name="green">
        <color rgba="0 1 0 1"/>
      </material>
    </visual>
    <collision>
      <origin rpy="0 0 0" xyz="0 0 0.017"/>
      <geometry>
        <box size="0.052 0.031 0.033"/>
      </geometry>
    </collision>
    <inertial>
      <origin rpy="0 0 0" xyz="0 0 0.017"/>
      <mass value="0.119"/>
      <inertia ixx="3.76139166667e-05" ixy="0" ixz="0" iyy="3.63445833333e-05" iyz="0" izz="2.03291666667e-05"/>
    </inertial>
  </link>
  <gazebo reference="head">
    <selfCollide>false</selfCollide>
    <mu1 value="0.8"/>
    <mu2 value="0.8"/>
    <material>Gazebo/Green</material>
  </gazebo>
  <transmission name="base_link_to_head_tran">
    <type>transmission_interface/SimpleTransmission</type>
    <joint name="base_link_to_head">
      <hardwareInterface>EffortJointInterface</hardwareInterface>
    </joint>
    <actuator name="head_motor">
      <hardwareInterface>EffortJointInterface</hardwareInterface>
      <mechanicalReduction>1</mechanicalReduction>
    </actuator>
  </transmission>
  <!-- base link (body)-->
  <link name="base_link">
    <visual>
      <origin rpy="0 0 0" xyz="0 0 0"/>
      <geometry>
        <box size="0.129 0.105 0.062"/>
      </geometry>
      <material name="green">
        <color rgba="0 1 0 1"/>
      </material>
    </visual>
    <collision>
      <origin rpy="0 0 0" xyz="0 0 0"/>
      <geometry>
        <box size="0.129 0.105 0.062"/>
      </geometry>
    </collision>
    <inertial>
      <origin rpy="0 0 0" xyz="0 0 0"/>
      <mass value="0.3655"/>
      <inertia ixx="0.000623938958333" ixy="0" ixz="0" iyy="0.00084266025" iyz="0" izz="0.000452884958333"/>
    </inertial>
  </link>
  <joint name="base_link_to_body_2" type="revolute">
    <parent link="base_link"/>
    <child link="body_2"/>
    <origin rpy="0 0 0" xyz="0 0 -0.0525"/>
    <axis xyz="0 0 1"/>
    <dynamics damping="0.5"/>
    <limit effort="0.5" lower="-0.785398185" upper="0.785398185" velocity="6.0"/>
  </joint>
  <link name="body_2">
    <visual>
      <origin rpy="0 0 0" xyz="0 0 0"/>
      <geometry>
        <box size="0.057 0.08 0.041"/>
      </geometry>
      <material name="green">
        <color rgba="0 1 0 1"/>
      </material>
    </visual>
    <collision>
      <origin rpy="0 0 0" xyz="0 0 0"/>
      <geometry>
        <box size="0.057 0.08 0.041"/>
      </geometry>
    </collision>
    <inertial>
      <origin rpy="0 0 0" xyz="0 0 0"/>
      <mass value="0.3655"/>
      <inertia ixx="0.000150159583333" ixy="0" ixz="0" iyy="0.000293892458333" iyz="0" izz="0.000246133791667"/>
    </inertial>
  </link>
  <gazebo reference="base_link">
    <selfCollide>false</selfCollide>
    <mu1 value="0.05"/>
    <mu2 value="0.05"/>
    <material>Gazebo/Green</material>
  </gazebo>
  <gazebo reference="body_2">
    <selfCollide>false</selfCollide>
    <mu1 value="0.8"/>
    <mu2 value="0.8"/>
    <material>Gazebo/Green</material>
  </gazebo>
  <transmission name="base_link_to_body_2_tran">
    <type>transmission_interface/SimpleTransmission</type>
    <joint name="base_link_to_body_2">
      <hardwareInterface>EffortJointInterface</hardwareInterface>
    </joint>
    <actuator name="body_motor">
      <hardwareInterface>EffortJointInterface</hardwareInterface>
      <mechanicalReduction>1</mechanicalReduction>
    </actuator>
  </transmission>
  <!-- left arm -->
  <joint name="base_link_to_Lshoulder" type="revolute">
    <parent link="base_link"/>
    <child link="Lshoulder"/>
    <origin rpy="0 0 0" xyz="0 0.0525 0.018"/>
    <axis xyz="0 1 0"/>
    <dynamics damping="0.5"/>
    <limit effort="0.5" lower="-3.14159274" upper="1.04719758" velocity="6.0"/>
  </joint>
  <link name="Lshoulder">
    <visual>
      <origin rpy="0 0 0" xyz="0 0.023 0"/>
      <geometry>
        <box size="0.026 0.026 0.036"/>
      </geometry>
      <material name="green">
        <color rgba="0 1 0 1"/>
      </material>
    </visual>
    <collision>
      <origin rpy="0 0 0" xyz="0 0.023 0"/>
      <geometry>
        <box size="0.026 0.026 0.036"/>
      </geometry>
    </collision>
    <inertial>
      <origin rpy="0 0 0" xyz="0 0.023 0"/>
      <mass value="0.02975"/>
      <inertia ixx="4.88891666667e-06" ixy="0" ixz="0" iyy="3.35183333333e-06" iyz="0" izz="4.88891666667e-06"/>
    </inertial>
  </link>
  <joint name="Lshoulder_to_Lupper_arm" type="revolute">
    <parent link="Lshoulder"/>
    <child link="Lupper_arm"/>
    <origin rpy="0 0 0" xyz="0 0.023 0"/>
    <axis xyz="1 0 0"/>
    <dynamics damping="0.5"/>
    <limit effort="0.5" lower="-0.0" upper="1.57079637" velocity="6.0"/>
  </joint>
  <link name="Lupper_arm">
    <visual>
      <origin rpy="0 0 0" xyz="0 0 -0.079"/>
      <geometry>
        <box size="0.026 0.026 0.082"/>
      </geometry>
      <material name="green">
        <color rgba="0 1 0 1"/>
      </material>
    </visual>
    <collision>
      <origin rpy="0 0 0" xyz="0 0 -0.079"/>
      <geometry>
        <box size="0.026 0.026 0.082"/>
      </geometry>
    </collision>
    <inertial>
      <origin rpy="0 0 0" xyz="0 0 -0.079"/>
      <mass value="0.02975"/>
      <inertia ixx="1.83458333333e-05" ixy="0" ixz="0" iyy="3.35183333333e-06" iyz="0" izz="1.83458333333e-05"/>
    </inertial>
  </link>
  <joint name="Lupper_arm_to_Llower_arm" type="revolute">
    <parent link="Lupper_arm"/>
    <child link="Llower_arm"/>
    <origin rpy="0 0 0" xyz="0.013 0 -0.125"/>
    <axis xyz="0 1 0"/>
    <dynamics damping="0.5"/>
    <limit effort="0.5" lower="-2.61799395" upper="0.0" velocity="6.0"/>
  </joint>
  <link name="Llower_arm">
    <visual>
      <origin rpy="0 0 0" xyz="-0.013 0 -0.033"/>
      <geometry>
        <box size="0.026 0.026 0.056"/>
      </geometry>
      <material name="green">
        <color rgba="0 1 0 1"/>
      </material>
    </visual>
    <collision>
      <origin rpy="0 0 0" xyz="-0.013 0 -0.033"/>
      <geometry>
        <box size="0.026 0.026 0.056"/>
      </geometry>
    </collision>
    <inertial>
      <origin rpy="0 0 0" xyz="-0.013 0 -0.033"/>
      <mass value="0.051"/>
      <inertia ixx="1.6201e-05" ixy="0" ixz="0" iyy="5.746e-06" iyz="0" izz="1.6201e-05"/>
    </inertial>
  </link>
  <gazebo reference="Lshoulder">
    <selfCollide>false</selfCollide>
    <mu1 value="0.8"/>
    <mu2 value="0.8"/>
    <material>Gazebo/Green</material>
  </gazebo>
  <gazebo reference="Lupper_arm">
    <selfCollide>false</selfCollide>
    <mu1 value="0.8"/>
    <mu2 value="0.8"/>
    <material>Gazebo/Green</material>
  </gazebo>
  <gazebo reference="Llower_arm">
    <selfCollide>false</selfCollide>
    <mu1 value="0.8"/>
    <mu2 value="0.8"/>
    <material>Gazebo/Green</material>
  </gazebo>
  <transmission name="base_link_to_Lshoulder_tran">
    <type>transmission_interface/SimpleTransmission</type>
    <joint name="base_link_to_Lshoulder">
      <hardwareInterface>EffortJointInterface</hardwareInterface>
    </joint>
    <actuator name="Larm_motor1">
      <hardwareInterface>EffortJointInterface</hardwareInterface>
      <mechanicalReduction>1</mechanicalReduction>
    </actuator>
  </transmission>
  <transmission name="Lshoulder_to_Lupper_arm_tran">
    <type>transmission_interface/SimpleTransmission</type>
    <joint name="Lshoulder_to_Lupper_arm">
      <hardwareInterface>EffortJointInterface</hardwareInterface>
    </joint>
    <actuator name="Larm_motor2">
      <hardwareInterface>EffortJointInterface</hardwareInterface>
      <mechanicalReduction>1</mechanicalReduction>
    </actuator>
  </transmission>
  <transmission name="Lupper_arm_to_Llower_arm_tran">
    <type>transmission_interface/SimpleTransmission</type>
    <joint name="Lupper_arm_to_Llower_arm">
      <hardwareInterface>EffortJointInterface</hardwareInterface>
    </joint>
    <actuator name="Larm_motor3">
      <hardwareInterface>EffortJointInterface</hardwareInterface>
      <mechanicalReduction>1</mechanicalReduction>
    </actuator>
  </transmission>
  <!-- right arm -->
  <joint name="base_link_to_Rshoulder" type="revolute">
    <parent link="base_link"/>
    <child link="Rshoulder"/>
    <origin rpy="0 0 0" xyz="0 -0.0525 0.018"/>
    <axis xyz="0 1 0"/>
    <dynamics damping="0.5"/>
    <limit effort="0.5" lower="-3.14159274" upper="1.04719758" velocity="6.0"/>
  </joint>
  <link name="Rshoulder">
    <visual>
      <origin rpy="0 0 0" xyz="0 -0.023 0"/>
      <geometry>
        <box size="0.026 0.026 0.036"/>
      </geometry>
      <material name="green">
        <color rgba="0 1 0 1"/>
      </material>
    </visual>
    <collision>
      <origin rpy="0 0 0" xyz="0 -0.023 0"/>
      <geometry>
        <box size="0.026 0.026 0.036"/>
      </geometry>
    </collision>
    <inertial>
      <origin rpy="0 0 0" xyz="0 -0.023 0"/>
      <mass value="0.02975"/>
      <inertia ixx="4.88891666667e-06" ixy="0" ixz="0" iyy="3.35183333333e-06" iyz="0" izz="4.88891666667e-06"/>
    </inertial>
  </link>
  <joint name="Rshoulder_to_Rupper_arm" type="revolute">
    <parent link="Rshoulder"/>
    <child link="Rupper_arm"/>
    <origin rpy="0 0 0" xyz="0 -0.023 0"/>
    <axis xyz="1 0 0"/>
    <dynamics damping="0.5"/>
    <limit effort="0.5" lower="-1.57079637" upper="0.0" velocity="6.0"/>
  </joint>
  <link name="Rupper_arm">
    <visual>
      <origin rpy="0 0 0" xyz="0 0 -0.079"/>
      <geometry>
        <box size="0.026 0.026 0.082"/>
      </geometry>
      <material name="green">
        <color rgba="0 1 0 1"/>
      </material>
    </visual>
    <collision>
      <origin rpy="0 0 0" xyz="0 0 -0.079"/>
      <geometry>
        <box size="0.026 0.026 0.082"/>
      </geometry>
    </collision>
    <inertial>
      <origin rpy="0 0 0" xyz="0 0 -0.079"/>
      <mass value="0.02975"/>
      <inertia ixx="1.83458333333e-05" ixy="0" ixz="0" iyy="3.35183333333e-06" iyz="0" izz="1.83458333333e-05"/>
    </inertial>
  </link>
  <joint name="Rupper_arm_to_Rlower_arm" type="revolute">
    <parent link="Rupper_arm"/>
    <child link="Rlower_arm"/>
    <origin rpy="0 0 0" xyz="0.013 0 -0.125"/>
    <axis xyz="0 1 0"/>
    <dynamics damping="0.5"/>
    <limit effort="0.5" lower="-2.61799395" upper="0.0" velocity="6.0"/>
  </joint>
  <link name="Rlower_arm">
    <visual>
      <origin rpy="0 0 0" xyz="-0.013 0 -0.033"/>
      <geometry>
        <box size="0.026 0.026 0.056"/>
      </geometry>
      <material name="green">
        <color rgba="0 1 0 1"/>
      </material>
    </visual>
    <collision>
      <origin rpy="0 0 0" xyz="-0.013 0 -0.033"/>
      <geometry>
        <box size="0.026 0.026 0.056"/>
      </geometry>
    </collision>
    <inertial>
      <origin rpy="0 0 0" xyz="-0.013 0 -0.033"/>
      <mass value="0.051"/>
      <inertia ixx="1.6201e-05" ixy="0" ixz="0" iyy="5.746e-06" iyz="0" izz="1.6201e-05"/>
    </inertial>
  </link>
  <gazebo reference="Rshoulder">
    <selfCollide>false</selfCollide>
    <mu1 value="0.8"/>
    <mu2 value="0.8"/>
    <material>Gazebo/Green</material>
  </gazebo>
  <gazebo reference="Rupper_arm">
    <selfCollide>false</selfCollide>
    <mu1 value="0.8"/>
    <mu2 value="0.8"/>
    <material>Gazebo/Green</material>
  </gazebo>
  <gazebo reference="Rlower_arm">
    <selfCollide>false</selfCollide>
    <mu1 value="0.8"/>
    <mu2 value="0.8"/>
    <material>Gazebo/Green</material>
  </gazebo>
  <transmission name="base_link_to_Rshoulder_tran">
    <type>transmission_interface/SimpleTransmission</type>
    <joint name="base_link_to_Rshoulder">
      <hardwareInterface>EffortJointInterface</hardwareInterface>
    </joint>
    <actuator name="Rarm_motor1">
      <hardwareInterface>EffortJointInterface</hardwareInterface>
      <mechanicalReduction>1</mechanicalReduction>
    </actuator>
  </transmission>
  <transmission name="Rshoulder_to_Rupper_arm_tran">
    <type>transmission_interface/SimpleTransmission</type>
    <joint name="Rshoulder_to_Rupper_arm">
      <hardwareInterface>EffortJointInterface</hardwareInterface>
    </joint>
    <actuator name="Rarm_motor2">
      <hardwareInterface>EffortJointInterface</hardwareInterface>
      <mechanicalReduction>1</mechanicalReduction>
    </actuator>
  </transmission>
  <transmission name="Rupper_arm_to_Rlower_arm_tran">
    <type>transmission_interface/SimpleTransmission</type>
    <joint name="Rupper_arm_to_Rlower_arm">
      <hardwareInterface>EffortJointInterface</hardwareInterface>
    </joint>
    <actuator name="Rarm_motor3">
      <hardwareInterface>EffortJointInterface</hardwareInterface>
      <mechanicalReduction>1</mechanicalReduction>
    </actuator>
  </transmission>
  <!-- left leg -->
  <joint name="body_2_to_Lhips" type="revolute">
    <parent link="body_2"/>
    <child link="Lhips"/>
    <origin rpy="0 0 0" xyz="0 0.03 -0.0255"/>
    <axis xyz="0 0 1"/>
    <dynamics damping="0.5"/>
    <limit effort="0.5" lower="-0.52359879" upper="0.785398185" velocity="6.0"/>
  </joint>
  <link name="Lhips">
    <visual>
      <origin rpy="0 0 0" xyz="0 0 0"/>
      <geometry>
        <box size="0.03 0.03 0.0039"/>
      </geometry>
      <material name="green">
        <color rgba="0 1 0 1"/>
      </material>
    </visual>
    <collision>
      <origin rpy="0 0 0" xyz="0 0 0"/>
      <geometry>
        <box size="0.03 0.03 0.0039"/>
      </geometry>
    </collision>
    <inertial>
      <origin rpy="0 0 0" xyz="0 0 0"/>
      <mass value="0.03944"/>
      <inertia ixx="3.0079902e-06" ixy="0" ixz="0" iyy="5.916e-06" iyz="0" izz="3.0079902e-06"/>
    </inertial>
  </link>
  <joint name="Lhips_to_Lthigh" type="revolute">
    <parent link="Lhips"/>
    <child link="Lthigh"/>
    <origin rpy="0 0 0" xyz="0 0 -0.030"/>
    <axis xyz="1 0 0"/>
    <dynamics damping="0.5"/>
    <limit effort="0.5" lower="-0.52359879" upper="0.785398185" velocity="6.0"/>
  </joint>
  <link name="Lthigh">
    <visual>
      <origin rpy="0 0 0" xyz="0 0 0"/>
      <geometry>
        <box size="0.03 0.03 0.026"/>
      </geometry>
      <material name="green">
        <color rgba="0 1 0 1"/>
      </material>
    </visual>
    <collision>
      <origin rpy="0 0 0" xyz="0 0 0"/>
      <geometry>
        <box size="0.03 0.03 0.026"/>
      </geometry>
    </collision>
    <inertial>
      <origin rpy="0 0 0" xyz="0 0 0"/>
      <mass value="0.03944"/>
      <inertia ixx="5.17978666667e-06" ixy="0" ixz="0" iyy="5.916e-06" iyz="0" izz="5.17978666667e-06"/>
    </inertial>
  </link>
  <joint name="Lthigh_to_Lknee" type="revolute">
    <parent link="Lthigh"/>
    <child link="Lknee"/>
    <origin rpy="0 0 0" xyz="0 0 -0.046"/>
    <axis xyz="0 1 0"/>
    <dynamics damping="0.5"/>
    <limit effort="0.5" lower="-2.09439516" upper="0.785398185" velocity="6.0"/>
  </joint>
  <link name="Lknee">
    <visual>
      <origin rpy="0 0 0" xyz="0 0 -0.034"/>
      <geometry>
        <box size="0.03 0.03 0.088"/>
      </geometry>
      <material name="green">
        <color rgba="0 1 0 1"/>
      </material>
    </visual>
    <collision>
      <origin rpy="0 0 0" xyz="0 0 -0.034"/>
      <geometry>
        <box size="0.03 0.03 0.088"/>
      </geometry>
    </collision>
    <inertial>
      <origin rpy="0 0 0" xyz="0 0 -0.034"/>
      <mass value="0.11832"/>
      <inertia ixx="8.522984e-05" ixy="0" ixz="0" iyy="1.7748e-05" iyz="0" izz="8.522984e-05"/>
    </inertial>
  </link>
  <joint name="Lknee_to_Lshin" type="revolute">
    <parent link="Lknee"/>
    <child link="Lshin"/>
    <origin rpy="0 0 0" xyz="-0.0205 0 -0.0885"/>
    <axis xyz="0 1 0"/>
    <dynamics damping="0.5"/>
    <limit effort="0.5" lower="-0.0" upper="2.61799395" velocity="6.0"/>
  </joint>
  <link name="Lshin">
    <visual>
      <origin rpy="0 0 0" xyz="0.0205 0 -0.024"/>
      <geometry>
        <box size="0.03 0.03 0.047"/>
      </geometry>
      <material name="green">
        <color rgba="0 1 0 1"/>
      </material>
    </visual>
    <collision>
      <origin rpy="0 0 0" xyz="0.0205 0 -0.024"/>
      <geometry>
        <box size="0.03 0.03 0.047"/>
      </geometry>
    </collision>
    <inertial>
      <origin rpy="0 0 0" xyz="0.0205 0 -0.024"/>
      <mass value="0.04692"/>
      <inertia ixx="1.215619e-05" ixy="0" ixz="0" iyy="7.038e-06" iyz="0" izz="1.215619e-05"/>
    </inertial>
  </link>
  <joint name="Lshin_to_Lankle" type="revolute">
    <parent link="Lshin"/>
    <child link="Lankle"/>
    <origin rpy="0 0 0" xyz="0.0205 0 -0.0319"/>
    <axis xyz="0 1 0"/>
    <dynamics damping="0.5"/>
    <limit effort="0.5" lower="-1.57079637" upper="1.04719758" velocity="6.0"/>
  </joint>
  <link name="Lankle">
    <visual>
      <origin rpy="0 0 0" xyz="0 0 -0.037"/>
      <geometry>
        <box size="0.03 0.03 0.02"/>
      </geometry>
      <material name="green">
        <color rgba="0 1 0 1"/>
      </material>
    </visual>
    <collision>
      <origin rpy="0 0 0" xyz="0 0 -0.037"/>
      <geometry>
        <box size="0.03 0.03 0.02"/>
      </geometry>
    </collision>
    <inertial>
      <origin rpy="0 0 0" xyz="0 0 -0.037"/>
      <mass value="0.04692"/>
      <inertia ixx="5.083e-06" ixy="0" ixz="0" iyy="7.038e-06" iyz="0" izz="5.083e-06"/>
    </inertial>
  </link>
  <joint name="Lankle_to_Lfoot" type="revolute">
    <parent link="Lankle"/>
    <child link="Lfoot"/>
    <origin rpy="0 0 0" xyz="0 0 -0.037"/>
    <axis xyz="1 0 0"/>
    <dynamics damping="0.5"/>
    <limit effort="0.5" lower="-0.785398185" upper="0.785398185" velocity="6.0"/>
  </joint>
  <link name="Lfoot">
    <visual>
      <origin rpy="0 0 0" xyz="0 0.0185 -0.0315"/>
      <geometry>
        <box size="0.122 0.078 0.01"/>
      </geometry>
      <material name="green">
        <color rgba="0 1 0 1"/>
      </material>
    </visual>
    <collision>
      <origin rpy="0 0 0" xyz="0 0.0185 -0.0315"/>
      <geometry>
        <box size="0.122 0.078 0.01"/>
      </geometry>
    </collision>
    <inertial>
      <origin rpy="0 0 0" xyz="0 0.0185 -0.0315"/>
      <mass value="0.02346"/>
      <inertia ixx="2.929372e-05" ixy="0" ixz="0" iyy="4.099244e-05" iyz="0" izz="1.208972e-05"/>
    </inertial>
  </link>
  <joint name="Lfsensor1_joint" type="fixed">
    <origin rpy="0 0 0" xyz="0 0 -0.0365"/>
    <parent link="Lfoot"/>
    <child link="Lfsensor1"/>
  </joint>
  <link name="Lfsensor1">
 		</link>
  <sensor name="Lfsensor1_sensor" update_rate="20">
    <origin rpy="0 0 0" xyz="0 0 -0.0365"/>
    <parent link="Lfoot"/>
  </sensor>
  <gazebo reference="Lhips">
    <selfCollide>false</selfCollide>
    <mu1 value="0.8"/>
    <mu2 value="0.8"/>
    <material>Gazebo/Green</material>
  </gazebo>
  <gazebo reference="Lthigh">
    <selfCollide>false</selfCollide>
    <mu1 value="0.8"/>
    <mu2 value="0.8"/>
    <material>Gazebo/Green</material>
  </gazebo>
  <gazebo reference="Lknee">
    <selfCollide>false</selfCollide>
    <mu1 value="0.8"/>
    <mu2 value="0.8"/>
    <material>Gazebo/Green</material>
  </gazebo>
  <gazebo reference="Lshin">
    <selfCollide>false</selfCollide>
    <mu1 value="0.8"/>
    <mu2 value="0.8"/>
    <material>Gazebo/Green</material>
  </gazebo>
  <gazebo reference="Lankle">
    <selfCollide>false</selfCollide>
    <mu1 value="0.8"/>
    <mu2 value="0.8"/>
    <material>Gazebo/Green</material>
  </gazebo>
  <gazebo reference="Lfoot">
    <selfCollide>false</selfCollide>
    <mu1 value="0.8"/>
    <mu2 value="0.8"/>
    <material>Gazebo/Green</material>
  </gazebo>
  <transmission name="body_2_to_Lhips_tran">
    <type>transmission_interface/SimpleTransmission</type>
    <joint name="body_2_to_Lhips">
      <hardwareInterface>EffortJointInterface</hardwareInterface>
    </joint>
    <actuator name="Lleg_motor1">
      <hardwareInterface>EffortJointInterface</hardwareInterface>
      <mechanicalReduction>1</mechanicalReduction>
    </actuator>
  </transmission>
  <transmission name="Lhips_to_Lthigh_tran">
    <type>transmission_interface/SimpleTransmission</type>
    <joint name="Lhips_to_Lthigh">
      <hardwareInterface>EffortJointInterface</hardwareInterface>
    </joint>
    <actuator name="Lleg_motor2">
      <hardwareInterface>EffortJointInterface</hardwareInterface>
      <mechanicalReduction>1</mechanicalReduction>
    </actuator>
  </transmission>
  <transmission name="Lthigh_to_Lknee_tran">
    <type>transmission_interface/SimpleTransmission</type>
    <joint name="Lthigh_to_Lknee">
      <hardwareInterface>EffortJointInterface</hardwareInterface>
    </joint>
    <actuator name="Lleg_motor3">
      <hardwareInterface>EffortJointInterface</hardwareInterface>
      <mechanicalReduction>1</mechanicalReduction>
    </actuator>
  </transmission>
  <transmission name="Lknee_to_Lshin_tran">
    <type>transmission_interface/SimpleTransmission</type>
    <joint name="Lknee_to_Lshin">
      <hardwareInterface>EffortJointInterface</hardwareInterface>
    </joint>
    <actuator name="Lleg_motor4">
      <hardwareInterface>EffortJointInterface</hardwareInterface>
      <mechanicalReduction>1</mechanicalReduction>
    </actuator>
  </transmission>
  <transmission name="Lshin_to_Lankle_tran">
    <type>transmission_interface/SimpleTransmission</type>
    <joint name="Lshin_to_Lankle">
      <hardwareInterface>EffortJointInterface</hardwareInterface>
    </joint>
    <actuator name="Lleg_motor5">
      <hardwareInterface>EffortJointInterface</hardwareInterface>
      <mechanicalReduction>1</mechanicalReduction>
    </actuator>
  </transmission>
  <transmission name="Lankle_to_Lfoot_tran">
    <type>transmission_interface/SimpleTransmission</type>
    <joint name="Lankle_to_Lfoot">
      <hardwareInterface>EffortJointInterface</hardwareInterface>
    </joint>
    <actuator name="Lleg_motor6">
      <hardwareInterface>EffortJointInterface</hardwareInterface>
      <mechanicalReduction>1</mechanicalReduction>
    </actuator>
  </transmission>
  <!-- right leg -->
  <joint name="body_2_to_Rhips" type="revolute">
    <parent link="body_2"/>
    <child link="Rhips"/>
    <origin rpy="0 0 0" xyz="0 -0.03 -0.0255"/>
    <axis xyz="0 0 1"/>
    <dynamics damping="0.5"/>
    <limit effort="0.5" lower="-0.785398185" upper="0.52359879" velocity="6.0"/>
  </joint>
  <link name="Rhips">
    <visual>
      <origin rpy="0 0 0" xyz="0 0 0"/>
      <geometry>
        <box size="0.03 0.03 0.0039"/>
      </geometry>
      <material name="green">
        <color rgba="0 1 0 1"/>
      </material>
    </visual>
    <collision>
      <origin rpy="0 0 0" xyz="0 0 0"/>
      <geometry>
        <box size="0.03 0.03 0.0039"/>
      </geometry>
    </collision>
    <inertial>
      <origin rpy="0 0 0" xyz="0 0 0"/>
      <mass value="0.03944"/>
      <inertia ixx="3.0079902e-06" ixy="0" ixz="0" iyy="5.916e-06" iyz="0" izz="3.0079902e-06"/>
    </inertial>
  </link>
  <joint name="Rhips_to_Rthigh" type="revolute">
    <parent link="Rhips"/>
    <child link="Rthigh"/>
    <origin rpy="0 0 0" xyz="0 0 -0.030"/>
    <axis xyz="1 0 0"/>
    <dynamics damping="0.5"/>
    <limit effort="0.5" lower="-0.785398185" upper="0.52359879" velocity="6.0"/>
  </joint>
  <link name="Rthigh">
    <visual>
      <origin rpy="0 0 0" xyz="0 0 0"/>
      <geometry>
        <box size="0.03 0.03 0.026"/>
      </geometry>
      <material name="green">
        <color rgba="0 1 0 1"/>
      </material>
    </visual>
    <collision>
      <origin rpy="0 0 0" xyz="0 0 0"/>
      <geometry>
        <box size="0.03 0.03 0.026"/>
      </geometry>
    </collision>
    <inertial>
      <origin rpy="0 0 0" xyz="0 0 0"/>
      <mass value="0.03944"/>
      <inertia ixx="5.17978666667e-06" ixy="0" ixz="0" iyy="5.916e-06" iyz="0" izz="5.17978666667e-06"/>
    </inertial>
  </link>
  <joint name="Rthigh_to_Rknee" type="revolute">
    <parent link="Rthigh"/>
    <child link="Rknee"/>
    <origin rpy="0 0 0" xyz="0 0 -0.046"/>
    <axis xyz="0 1 0"/>
    <dynamics damping="0.5"/>
    <limit effort="0.5" lower="-2.09439516" upper="0.785398185" velocity="6.0"/>
  </joint>
  <link name="Rknee">
    <visual>
      <origin rpy="0 0 0" xyz="0 0 -0.034"/>
      <geometry>
        <box size="0.03 0.03 0.088"/>
      </geometry>
      <material name="green">
        <color rgba="0 1 0 1"/>
      </material>
    </visual>
    <collision>
      <origin rpy="0 0 0" xyz="0 0 -0.034"/>
      <geometry>
        <box size="0.03 0.03 0.088"/>
      </geometry>
    </collision>
    <inertial>
      <origin rpy="0 0 0" xyz="0 0 -0.034"/>
      <mass value="0.11832"/>
      <inertia ixx="8.522984e-05" ixy="0" ixz="0" iyy="1.7748e-05" iyz="0" izz="8.522984e-05"/>
    </inertial>
  </link>
  <joint name="Rknee_to_Rshin" type="revolute">
    <parent link="Rknee"/>
    <child link="Rshin"/>
    <origin rpy="0 0 0" xyz="-0.0205 0 -0.0885"/>
    <axis xyz="0 1 0"/>
    <dynamics damping="0.5"/>
    <limit effort="0.5" lower="-0.0" upper="2.61799395" velocity="6.0"/>
  </joint>
  <link name="Rshin">
    <visual>
      <origin rpy="0 0 0" xyz="0.0205 0 -0.024"/>
      <geometry>
        <box size="0.03 0.03 0.047"/>
      </geometry>
      <material name="green">
        <color rgba="0 1 0 1"/>
      </material>
    </visual>
    <collision>
      <origin rpy="0 0 0" xyz="0.0205 0 -0.024"/>
      <geometry>
        <box size="0.03 0.03 0.047"/>
      </geometry>
    </collision>
    <inertial>
      <origin rpy="0 0 0" xyz="0.0205 0 -0.024"/>
      <mass value="0.04692"/>
      <inertia ixx="1.215619e-05" ixy="0" ixz="0" iyy="7.038e-06" iyz="0" izz="1.215619e-05"/>
    </inertial>
  </link>
  <joint name="Rshin_to_Rankle" type="revolute">
    <parent link="Rshin"/>
    <child link="Rankle"/>
    <origin rpy="0 0 0" xyz="0.0205 0 -0.0319"/>
    <axis xyz="0 1 0"/>
    <dynamics damping="0.5"/>
    <limit effort="0.5" lower="-1.57079637" upper="1.04719758" velocity="6.0"/>
  </joint>
  <link name="Rankle">
    <visual>
      <origin rpy="0 0 0" xyz="0 0 -0.037"/>
      <geometry>
        <box size="0.03 0.03 0.02"/>
      </geometry>
      <material name="green">
        <color rgba="0 1 0 1"/>
      </material>
    </visual>
    <collision>
      <origin rpy="0 0 0" xyz="0 0 -0.037"/>
      <geometry>
        <box size="0.03 0.03 0.02"/>
      </geometry>
    </collision>
    <inertial>
      <origin rpy="0 0 0" xyz="0 0 -0.037"/>
      <mass value="0.04692"/>
      <inertia ixx="5.083e-06" ixy="0" ixz="0" iyy="7.038e-06" iyz="0" izz="5.083e-06"/>
    </inertial>
  </link>
  <joint name="Rankle_to_Rfoot" type="revolute">
    <parent link="Rankle"/>
    <child link="Rfoot"/>
    <origin rpy="0 0 0" xyz="0 0 -0.037"/>
    <axis xyz="1 0 0"/>
    <dynamics damping="0.5"/>
    <limit effort="0.5" lower="-0.785398185" upper="0.785398185" velocity="6.0"/>
  </joint>
  <link name="Rfoot">
    <visual>
      <origin rpy="0 0 0" xyz="0 -0.0185 -0.0315"/>
      <geometry>
        <box size="0.122 0.078 0.01"/>
      </geometry>
      <material name="green">
        <color rgba="0 1 0 1"/>
      </material>
    </visual>
    <collision>
      <origin rpy="0 0 0" xyz="0 -0.0185 -0.0315"/>
      <geometry>
        <box size="0.122 0.078 0.01"/>
      </geometry>
    </collision>
    <inertial>
      <origin rpy="0 0 0" xyz="0 -0.0185 -0.0315"/>
      <mass value="0.02346"/>
      <inertia ixx="2.929372e-05" ixy="0" ixz="0" iyy="4.099244e-05" iyz="0" izz="1.208972e-05"/>
    </inertial>
  </link>
  <joint name="Rfsensor1_joint" type="fixed">
    <origin rpy="0 0 0" xyz="0 0 -0.0365"/>
    <parent link="Rfoot"/>
    <child link="Rfsensor1"/>
  </joint>
  <link name="Rfsensor1">
 		</link>
  <sensor name="Rfsensor1_sensor" update_rate="20">
    <origin rpy="0 0 0" xyz="0 0 -0.0365"/>
    <parent link="Rfoot"/>
  </sensor>
  <gazebo reference="Rhips">
    <selfCollide>false</selfCollide>
    <mu1 value="0.8"/>
    <mu2 value="0.8"/>
    <material>Gazebo/Green</material>
  </gazebo>
  <gazebo reference="Rthigh">
    <selfCollide>false</selfCollide>
    <mu1 value="0.8"/>
    <mu2 value="0.8"/>
    <material>Gazebo/Green</material>
  </gazebo>
  <gazebo reference="Rknee">
    <selfCollide>false</selfCollide>
    <mu1 value="0.8"/>
    <mu2 value="0.8"/>
    <material>Gazebo/Green</material>
  </gazebo>
  <gazebo reference="Rshin">
    <selfCollide>false</selfCollide>
    <mu1 value="0.8"/>
    <mu2 value="0.8"/>
    <material>Gazebo/Green</material>
  </gazebo>
  <gazebo reference="Rankle">
    <selfCollide>false</selfCollide>
    <mu1 value="0.8"/>
    <mu2 value="0.8"/>
    <material>Gazebo/Green</material>
  </gazebo>
  <gazebo reference="Rfoot">
    <selfCollide>false</selfCollide>
    <mu1 value="0.8"/>
    <mu2 value="0.8"/>
    <material>Gazebo/Green</material>
  </gazebo>
  <transmission name="body_2_to_Rhips_tran">
    <type>transmission_interface/SimpleTransmission</type>
    <joint name="body_2_to_Rhips">
      <hardwareInterface>EffortJointInterface</hardwareInterface>
    </joint>
    <actuator name="Rleg_motor1">
      <hardwareInterface>EffortJointInterface</hardwareInterface>
      <mechanicalReduction>1</mechanicalReduction>
    </actuator>
  </transmission>
  <transmission name="Rhips_to_Rthigh_tran">
    <type>transmission_interface/SimpleTransmission</type>
    <joint name="Rhips_to_Rthigh">
      <hardwareInterface>EffortJointInterface</hardwareInterface>
    </joint>
    <actuator name="Rleg_motor2">
      <hardwareInterface>EffortJointInterface</hardwareInterface>
      <mechanicalReduction>1</mechanicalReduction>
    </actuator>
  </transmission>
  <transmission name="Rthigh_to_Rknee_tran">
    <type>transmission_interface/SimpleTransmission</type>
    <joint name="Rthigh_to_Rknee">
      <hardwareInterface>EffortJointInterface</hardwareInterface>
    </joint>
    <actuator name="Rleg_motor3">
      <hardwareInterface>EffortJointInterface</hardwareInterface>
      <mechanicalReduction>1</mechanicalReduction>
    </actuator>
  </transmission>
  <transmission name="Rknee_to_Rshin_tran">
    <type>transmission_interface/SimpleTransmission</type>
    <joint name="Rknee_to_Rshin">
      <hardwareInterface>EffortJointInterface</hardwareInterface>
    </joint>
    <actuator name="Rleg_motor4">
      <hardwareInterface>EffortJointInterface</hardwareInterface>
      <mechanicalReduction>1</mechanicalReduction>
    </actuator>
  </transmission>
  <transmission name="Rshin_to_Rankle_tran">
    <type>transmission_interface/SimpleTransmission</type>
    <joint name="Rshin_to_Rankle">
      <hardwareInterface>EffortJointInterface</hardwareInterface>
    </joint>
    <actuator name="Rleg_motor5">
      <hardwareInterface>EffortJointInterface</hardwareInterface>
      <mechanicalReduction>1</mechanicalReduction>
    </actuator>
  </transmission>
  <transmission name="Rankle_to_Rfoot_tran">
    <type>transmission_interface/SimpleTransmission</type>
    <joint name="Rankle_to_Rfoot">
      <hardwareInterface>EffortJointInterface</hardwareInterface>
    </joint>
    <actuator name="Rleg_motor6">
      <hardwareInterface>EffortJointInterface</hardwareInterface>
      <mechanicalReduction>1</mechanicalReduction>
    </actuator>
  </transmission>
</robot>

=======
<?xml version="1.0" ?>
<!-- =================================================================================== -->
<!-- |    This document was autogenerated by xacro from khr-3hv_urdf.xacro             | -->
<!-- |    EDITING THIS FILE BY HAND IS NOT RECOMMENDED                                 | -->
<!-- =================================================================================== -->
<robot name="khr-3hv" xmlns:xacro="http://ros.org/wiki/xacro">
  <!-- ros_control plugin -->
  <!-- common color -->
  <!-- calculate box inertia -->
  <!-- ros_control plugin -->
  <!-- common color -->
  <!-- calculate box inertia -->
  <!-- ros_control plugin -->
  <!-- common color -->
  <!-- calculate box inertia -->
  <!-- ros_control plugin -->
  <!-- common color -->
  <!-- calculate box inertia -->
  <!-- ros_control plugin -->
  <!-- common color -->
  <!-- calculate box inertia -->
  <!-- ros_control plugin -->
  <!-- ros_control plugin -->
  <gazebo>
    <plugin filename="libgazebo_ros_control.so" name="gazebo_ros_control">
      <robotNamespace>/khr-3hv</robotNamespace>
      <robotSimType>gazebo_ros_control/DefaultRobotHWSim</robotSimType>
    </plugin>
  </gazebo>
  <!-- head -->
  <joint name="base_link_to_head" type="revolute">
    <parent link="base_link"/>
    <child link="head"/>
    <origin rpy="0 0 0" xyz="0 0 0.0315"/>
    <axis xyz="0 0 1"/>
    <dynamics damping="0.5"/>
    <limit effort="0.5" lower="-1.57079637" upper="1.57079637" velocity="6.0"/>
  </joint>
  <link name="head">
    <visual>
      <origin rpy="0 0 0" xyz="0 0 0.017"/>
      <geometry>
        <box size="0.052 0.031 0.033"/>
      </geometry>
      <material name="green">
        <color rgba="0 1 0 1"/>
      </material>
    </visual>
    <collision>
      <origin rpy="0 0 0" xyz="0 0 0.017"/>
      <geometry>
        <box size="0.052 0.031 0.033"/>
      </geometry>
    </collision>
    <inertial>
      <origin rpy="0 0 0" xyz="0 0 0.017"/>
      <mass value="0.119"/>
      <inertia ixx="3.76139166667e-05" ixy="0" ixz="0" iyy="3.63445833333e-05" iyz="0" izz="2.03291666667e-05"/>
    </inertial>
  </link>
  <gazebo reference="head">
    <selfCollide>false</selfCollide>
    <mu1 value="0.8"/>
    <mu2 value="0.8"/>
    <material>Gazebo/Green</material>
  </gazebo>
  <transmission name="base_link_to_head_tran">
    <type>transmission_interface/SimpleTransmission</type>
    <joint name="base_link_to_head">
      <hardwareInterface>EffortJointInterface</hardwareInterface>
    </joint>
    <actuator name="head_motor">
      <hardwareInterface>EffortJointInterface</hardwareInterface>
      <mechanicalReduction>1</mechanicalReduction>
    </actuator>
  </transmission>
  <!-- base link (body)-->
  <link name="base_link">
    <visual>
      <origin rpy="0 0 0" xyz="0 0 0"/>
      <geometry>
        <box size="0.129 0.105 0.062"/>
      </geometry>
      <material name="green">
        <color rgba="0 1 0 1"/>
      </material>
    </visual>
    <collision>
      <origin rpy="0 0 0" xyz="0 0 0"/>
      <geometry>
        <box size="0.129 0.105 0.062"/>
      </geometry>
    </collision>
    <inertial>
      <origin rpy="0 0 0" xyz="0 0 0"/>
      <mass value="0.3655"/>
      <inertia ixx="0.000623938958333" ixy="0" ixz="0" iyy="0.00084266025" iyz="0" izz="0.000452884958333"/>
    </inertial>
  </link>
  <joint name="base_link_to_body_2" type="revolute">
    <parent link="base_link"/>
    <child link="body_2"/>
    <origin rpy="0 0 0" xyz="0 0 -0.0525"/>
    <axis xyz="0 0 1"/>
    <dynamics damping="0.5"/>
    <limit effort="0.5" lower="-0.785398185" upper="0.785398185" velocity="6.0"/>
  </joint>
  <link name="body_2">
    <visual>
      <origin rpy="0 0 0" xyz="0 0 0"/>
      <geometry>
        <box size="0.057 0.08 0.041"/>
      </geometry>
      <material name="green">
        <color rgba="0 1 0 1"/>
      </material>
    </visual>
    <collision>
      <origin rpy="0 0 0" xyz="0 0 0"/>
      <geometry>
        <box size="0.057 0.08 0.041"/>
      </geometry>
    </collision>
    <inertial>
      <origin rpy="0 0 0" xyz="0 0 0"/>
      <mass value="0.3655"/>
      <inertia ixx="0.000150159583333" ixy="0" ixz="0" iyy="0.000293892458333" iyz="0" izz="0.000246133791667"/>
    </inertial>
  </link>
  <gazebo reference="base_link">
    <selfCollide>false</selfCollide>
    <mu1 value="0.05"/>
    <mu2 value="0.05"/>
    <material>Gazebo/Green</material>
  </gazebo>
  <gazebo reference="body_2">
    <selfCollide>false</selfCollide>
    <mu1 value="0.8"/>
    <mu2 value="0.8"/>
    <material>Gazebo/Green</material>
  </gazebo>
  <transmission name="base_link_to_body_2_tran">
    <type>transmission_interface/SimpleTransmission</type>
    <joint name="base_link_to_body_2">
      <hardwareInterface>EffortJointInterface</hardwareInterface>
    </joint>
    <actuator name="body_motor">
      <hardwareInterface>EffortJointInterface</hardwareInterface>
      <mechanicalReduction>1</mechanicalReduction>
    </actuator>
  </transmission>
  <!-- left arm -->
  <joint name="base_link_to_Lshoulder" type="revolute">
    <parent link="base_link"/>
    <child link="Lshoulder"/>
    <origin rpy="0 0 0" xyz="0 0.0525 0.018"/>
    <axis xyz="0 1 0"/>
    <dynamics damping="0.5"/>
    <limit effort="0.5" lower="-3.14159274" upper="1.04719758" velocity="6.0"/>
  </joint>
  <link name="Lshoulder">
    <visual>
      <origin rpy="0 0 0" xyz="0 0.023 0"/>
      <geometry>
        <box size="0.026 0.026 0.036"/>
      </geometry>
      <material name="green">
        <color rgba="0 1 0 1"/>
      </material>
    </visual>
    <collision>
      <origin rpy="0 0 0" xyz="0 0.023 0"/>
      <geometry>
        <box size="0.026 0.026 0.036"/>
      </geometry>
    </collision>
    <inertial>
      <origin rpy="0 0 0" xyz="0 0.023 0"/>
      <mass value="0.02975"/>
      <inertia ixx="4.88891666667e-06" ixy="0" ixz="0" iyy="3.35183333333e-06" iyz="0" izz="4.88891666667e-06"/>
    </inertial>
  </link>
  <joint name="Lshoulder_to_Lupper_arm" type="revolute">
    <parent link="Lshoulder"/>
    <child link="Lupper_arm"/>
    <origin rpy="0 0 0" xyz="0 0.023 0"/>
    <axis xyz="1 0 0"/>
    <dynamics damping="0.5"/>
    <limit effort="0.5" lower="-0.0" upper="1.57079637" velocity="6.0"/>
  </joint>
  <link name="Lupper_arm">
    <visual>
      <origin rpy="0 0 0" xyz="0 0 -0.079"/>
      <geometry>
        <box size="0.026 0.026 0.082"/>
      </geometry>
      <material name="green">
        <color rgba="0 1 0 1"/>
      </material>
    </visual>
    <collision>
      <origin rpy="0 0 0" xyz="0 0 -0.079"/>
      <geometry>
        <box size="0.026 0.026 0.082"/>
      </geometry>
    </collision>
    <inertial>
      <origin rpy="0 0 0" xyz="0 0 -0.079"/>
      <mass value="0.02975"/>
      <inertia ixx="1.83458333333e-05" ixy="0" ixz="0" iyy="3.35183333333e-06" iyz="0" izz="1.83458333333e-05"/>
    </inertial>
  </link>
  <joint name="Lupper_arm_to_Llower_arm" type="revolute">
    <parent link="Lupper_arm"/>
    <child link="Llower_arm"/>
    <origin rpy="0 0 0" xyz="0.013 0 -0.125"/>
    <axis xyz="0 1 0"/>
    <dynamics damping="0.5"/>
    <limit effort="0.5" lower="-2.61799395" upper="0.0" velocity="6.0"/>
  </joint>
  <link name="Llower_arm">
    <visual>
      <origin rpy="0 0 0" xyz="-0.013 0 -0.033"/>
      <geometry>
        <box size="0.026 0.026 0.056"/>
      </geometry>
      <material name="green">
        <color rgba="0 1 0 1"/>
      </material>
    </visual>
    <collision>
      <origin rpy="0 0 0" xyz="-0.013 0 -0.033"/>
      <geometry>
        <box size="0.026 0.026 0.056"/>
      </geometry>
    </collision>
    <inertial>
      <origin rpy="0 0 0" xyz="-0.013 0 -0.033"/>
      <mass value="0.051"/>
      <inertia ixx="1.6201e-05" ixy="0" ixz="0" iyy="5.746e-06" iyz="0" izz="1.6201e-05"/>
    </inertial>
  </link>
  <gazebo reference="Lshoulder">
    <selfCollide>false</selfCollide>
    <mu1 value="0.8"/>
    <mu2 value="0.8"/>
    <material>Gazebo/Green</material>
  </gazebo>
  <gazebo reference="Lupper_arm">
    <selfCollide>false</selfCollide>
    <mu1 value="0.8"/>
    <mu2 value="0.8"/>
    <material>Gazebo/Green</material>
  </gazebo>
  <gazebo reference="Llower_arm">
    <selfCollide>false</selfCollide>
    <mu1 value="0.8"/>
    <mu2 value="0.8"/>
    <material>Gazebo/Green</material>
  </gazebo>
  <transmission name="base_link_to_Lshoulder_tran">
    <type>transmission_interface/SimpleTransmission</type>
    <joint name="base_link_to_Lshoulder">
      <hardwareInterface>EffortJointInterface</hardwareInterface>
    </joint>
    <actuator name="Larm_motor1">
      <hardwareInterface>EffortJointInterface</hardwareInterface>
      <mechanicalReduction>1</mechanicalReduction>
    </actuator>
  </transmission>
  <transmission name="Lshoulder_to_Lupper_arm_tran">
    <type>transmission_interface/SimpleTransmission</type>
    <joint name="Lshoulder_to_Lupper_arm">
      <hardwareInterface>EffortJointInterface</hardwareInterface>
    </joint>
    <actuator name="Larm_motor2">
      <hardwareInterface>EffortJointInterface</hardwareInterface>
      <mechanicalReduction>1</mechanicalReduction>
    </actuator>
  </transmission>
  <transmission name="Lupper_arm_to_Llower_arm_tran">
    <type>transmission_interface/SimpleTransmission</type>
    <joint name="Lupper_arm_to_Llower_arm">
      <hardwareInterface>EffortJointInterface</hardwareInterface>
    </joint>
    <actuator name="Larm_motor3">
      <hardwareInterface>EffortJointInterface</hardwareInterface>
      <mechanicalReduction>1</mechanicalReduction>
    </actuator>
  </transmission>
  <!-- right arm -->
  <joint name="base_link_to_Rshoulder" type="revolute">
    <parent link="base_link"/>
    <child link="Rshoulder"/>
    <origin rpy="0 0 0" xyz="0 -0.0525 0.018"/>
    <axis xyz="0 1 0"/>
    <dynamics damping="0.5"/>
    <limit effort="0.5" lower="-3.14159274" upper="1.04719758" velocity="6.0"/>
  </joint>
  <link name="Rshoulder">
    <visual>
      <origin rpy="0 0 0" xyz="0 -0.023 0"/>
      <geometry>
        <box size="0.026 0.026 0.036"/>
      </geometry>
      <material name="green">
        <color rgba="0 1 0 1"/>
      </material>
    </visual>
    <collision>
      <origin rpy="0 0 0" xyz="0 -0.023 0"/>
      <geometry>
        <box size="0.026 0.026 0.036"/>
      </geometry>
    </collision>
    <inertial>
      <origin rpy="0 0 0" xyz="0 -0.023 0"/>
      <mass value="0.02975"/>
      <inertia ixx="4.88891666667e-06" ixy="0" ixz="0" iyy="3.35183333333e-06" iyz="0" izz="4.88891666667e-06"/>
    </inertial>
  </link>
  <joint name="Rshoulder_to_Rupper_arm" type="revolute">
    <parent link="Rshoulder"/>
    <child link="Rupper_arm"/>
    <origin rpy="0 0 0" xyz="0 -0.023 0"/>
    <axis xyz="1 0 0"/>
    <dynamics damping="0.5"/>
    <limit effort="0.5" lower="-1.57079637" upper="0.0" velocity="6.0"/>
  </joint>
  <link name="Rupper_arm">
    <visual>
      <origin rpy="0 0 0" xyz="0 0 -0.079"/>
      <geometry>
        <box size="0.026 0.026 0.082"/>
      </geometry>
      <material name="green">
        <color rgba="0 1 0 1"/>
      </material>
    </visual>
    <collision>
      <origin rpy="0 0 0" xyz="0 0 -0.079"/>
      <geometry>
        <box size="0.026 0.026 0.082"/>
      </geometry>
    </collision>
    <inertial>
      <origin rpy="0 0 0" xyz="0 0 -0.079"/>
      <mass value="0.02975"/>
      <inertia ixx="1.83458333333e-05" ixy="0" ixz="0" iyy="3.35183333333e-06" iyz="0" izz="1.83458333333e-05"/>
    </inertial>
  </link>
  <joint name="Rupper_arm_to_Rlower_arm" type="revolute">
    <parent link="Rupper_arm"/>
    <child link="Rlower_arm"/>
    <origin rpy="0 0 0" xyz="0.013 0 -0.125"/>
    <axis xyz="0 1 0"/>
    <dynamics damping="0.5"/>
    <limit effort="0.5" lower="-2.61799395" upper="0.0" velocity="6.0"/>
  </joint>
  <link name="Rlower_arm">
    <visual>
      <origin rpy="0 0 0" xyz="-0.013 0 -0.033"/>
      <geometry>
        <box size="0.026 0.026 0.056"/>
      </geometry>
      <material name="green">
        <color rgba="0 1 0 1"/>
      </material>
    </visual>
    <collision>
      <origin rpy="0 0 0" xyz="-0.013 0 -0.033"/>
      <geometry>
        <box size="0.026 0.026 0.056"/>
      </geometry>
    </collision>
    <inertial>
      <origin rpy="0 0 0" xyz="-0.013 0 -0.033"/>
      <mass value="0.051"/>
      <inertia ixx="1.6201e-05" ixy="0" ixz="0" iyy="5.746e-06" iyz="0" izz="1.6201e-05"/>
    </inertial>
  </link>
  <gazebo reference="Rshoulder">
    <selfCollide>false</selfCollide>
    <mu1 value="0.8"/>
    <mu2 value="0.8"/>
    <material>Gazebo/Green</material>
  </gazebo>
  <gazebo reference="Rupper_arm">
    <selfCollide>false</selfCollide>
    <mu1 value="0.8"/>
    <mu2 value="0.8"/>
    <material>Gazebo/Green</material>
  </gazebo>
  <gazebo reference="Rlower_arm">
    <selfCollide>false</selfCollide>
    <mu1 value="0.8"/>
    <mu2 value="0.8"/>
    <material>Gazebo/Green</material>
  </gazebo>
  <transmission name="base_link_to_Rshoulder_tran">
    <type>transmission_interface/SimpleTransmission</type>
    <joint name="base_link_to_Rshoulder">
      <hardwareInterface>EffortJointInterface</hardwareInterface>
    </joint>
    <actuator name="Rarm_motor1">
      <hardwareInterface>EffortJointInterface</hardwareInterface>
      <mechanicalReduction>1</mechanicalReduction>
    </actuator>
  </transmission>
  <transmission name="Rshoulder_to_Rupper_arm_tran">
    <type>transmission_interface/SimpleTransmission</type>
    <joint name="Rshoulder_to_Rupper_arm">
      <hardwareInterface>EffortJointInterface</hardwareInterface>
    </joint>
    <actuator name="Rarm_motor2">
      <hardwareInterface>EffortJointInterface</hardwareInterface>
      <mechanicalReduction>1</mechanicalReduction>
    </actuator>
  </transmission>
  <transmission name="Rupper_arm_to_Rlower_arm_tran">
    <type>transmission_interface/SimpleTransmission</type>
    <joint name="Rupper_arm_to_Rlower_arm">
      <hardwareInterface>EffortJointInterface</hardwareInterface>
    </joint>
    <actuator name="Rarm_motor3">
      <hardwareInterface>EffortJointInterface</hardwareInterface>
      <mechanicalReduction>1</mechanicalReduction>
    </actuator>
  </transmission>
  <!-- left leg -->
  <joint name="body_2_to_Lhips" type="revolute">
    <parent link="body_2"/>
    <child link="Lhips"/>
    <origin rpy="0 0 0" xyz="0 0.03 -0.0255"/>
    <axis xyz="0 0 1"/>
    <dynamics damping="0.5"/>
    <limit effort="0.5" lower="-0.52359879" upper="0.785398185" velocity="6.0"/>
  </joint>
  <link name="Lhips">
    <visual>
      <origin rpy="0 0 0" xyz="0 0 0"/>
      <geometry>
        <box size="0.03 0.03 0.0039"/>
      </geometry>
      <material name="green">
        <color rgba="0 1 0 1"/>
      </material>
    </visual>
    <collision>
      <origin rpy="0 0 0" xyz="0 0 0"/>
      <geometry>
        <box size="0.03 0.03 0.0039"/>
      </geometry>
    </collision>
    <inertial>
      <origin rpy="0 0 0" xyz="0 0 0"/>
      <mass value="0.03944"/>
      <inertia ixx="3.0079902e-06" ixy="0" ixz="0" iyy="5.916e-06" iyz="0" izz="3.0079902e-06"/>
    </inertial>
  </link>
  <joint name="Lhips_to_Lthigh" type="revolute">
    <parent link="Lhips"/>
    <child link="Lthigh"/>
    <origin rpy="0 0 0" xyz="0 0 -0.030"/>
    <axis xyz="1 0 0"/>
    <dynamics damping="0.5"/>
    <limit effort="0.5" lower="-0.52359879" upper="0.785398185" velocity="6.0"/>
  </joint>
  <link name="Lthigh">
    <visual>
      <origin rpy="0 0 0" xyz="0 0 0"/>
      <geometry>
        <box size="0.03 0.03 0.026"/>
      </geometry>
      <material name="green">
        <color rgba="0 1 0 1"/>
      </material>
    </visual>
    <collision>
      <origin rpy="0 0 0" xyz="0 0 0"/>
      <geometry>
        <box size="0.03 0.03 0.026"/>
      </geometry>
    </collision>
    <inertial>
      <origin rpy="0 0 0" xyz="0 0 0"/>
      <mass value="0.03944"/>
      <inertia ixx="5.17978666667e-06" ixy="0" ixz="0" iyy="5.916e-06" iyz="0" izz="5.17978666667e-06"/>
    </inertial>
  </link>
  <joint name="Lthigh_to_Lknee" type="revolute">
    <parent link="Lthigh"/>
    <child link="Lknee"/>
    <origin rpy="0 0 0" xyz="0 0 -0.046"/>
    <axis xyz="0 1 0"/>
    <dynamics damping="0.5"/>
    <limit effort="0.5" lower="-2.09439516" upper="0.785398185" velocity="6.0"/>
  </joint>
  <link name="Lknee">
    <visual>
      <origin rpy="0 0 0" xyz="0 0 -0.034"/>
      <geometry>
        <box size="0.03 0.03 0.088"/>
      </geometry>
      <material name="green">
        <color rgba="0 1 0 1"/>
      </material>
    </visual>
    <collision>
      <origin rpy="0 0 0" xyz="0 0 -0.034"/>
      <geometry>
        <box size="0.03 0.03 0.088"/>
      </geometry>
    </collision>
    <inertial>
      <origin rpy="0 0 0" xyz="0 0 -0.034"/>
      <mass value="0.11832"/>
      <inertia ixx="8.522984e-05" ixy="0" ixz="0" iyy="1.7748e-05" iyz="0" izz="8.522984e-05"/>
    </inertial>
  </link>
  <joint name="Lknee_to_Lshin" type="revolute">
    <parent link="Lknee"/>
    <child link="Lshin"/>
    <origin rpy="0 0 0" xyz="-0.0205 0 -0.0885"/>
    <axis xyz="0 1 0"/>
    <dynamics damping="0.5"/>
    <limit effort="0.5" lower="-0.0" upper="2.61799395" velocity="6.0"/>
  </joint>
  <link name="Lshin">
    <visual>
      <origin rpy="0 0 0" xyz="0.0205 0 -0.024"/>
      <geometry>
        <box size="0.03 0.03 0.047"/>
      </geometry>
      <material name="green">
        <color rgba="0 1 0 1"/>
      </material>
    </visual>
    <collision>
      <origin rpy="0 0 0" xyz="0.0205 0 -0.024"/>
      <geometry>
        <box size="0.03 0.03 0.047"/>
      </geometry>
    </collision>
    <inertial>
      <origin rpy="0 0 0" xyz="0.0205 0 -0.024"/>
      <mass value="0.04692"/>
      <inertia ixx="1.215619e-05" ixy="0" ixz="0" iyy="7.038e-06" iyz="0" izz="1.215619e-05"/>
    </inertial>
  </link>
  <joint name="Lshin_to_Lankle" type="revolute">
    <parent link="Lshin"/>
    <child link="Lankle"/>
    <origin rpy="0 0 0" xyz="0.0205 0 -0.0319"/>
    <axis xyz="0 1 0"/>
    <dynamics damping="0.5"/>
    <limit effort="0.5" lower="-1.57079637" upper="1.04719758" velocity="6.0"/>
  </joint>
  <link name="Lankle">
    <visual>
      <origin rpy="0 0 0" xyz="0 0 -0.037"/>
      <geometry>
        <box size="0.03 0.03 0.02"/>
      </geometry>
      <material name="green">
        <color rgba="0 1 0 1"/>
      </material>
    </visual>
    <collision>
      <origin rpy="0 0 0" xyz="0 0 -0.037"/>
      <geometry>
        <box size="0.03 0.03 0.02"/>
      </geometry>
    </collision>
    <inertial>
      <origin rpy="0 0 0" xyz="0 0 -0.037"/>
      <mass value="0.04692"/>
      <inertia ixx="5.083e-06" ixy="0" ixz="0" iyy="7.038e-06" iyz="0" izz="5.083e-06"/>
    </inertial>
  </link>
  <joint name="Lankle_to_Lfoot" type="revolute">
    <parent link="Lankle"/>
    <child link="Lfoot"/>
    <origin rpy="0 0 0" xyz="0 0 -0.037"/>
    <axis xyz="1 0 0"/>
    <dynamics damping="0.5"/>
    <limit effort="0.5" lower="-0.785398185" upper="0.785398185" velocity="6.0"/>
  </joint>
  <link name="Lfoot">
    <visual>
      <origin rpy="0 0 0" xyz="0 0.0185 -0.0315"/>
      <geometry>
        <box size="0.122 0.078 0.01"/>
      </geometry>
      <material name="green">
        <color rgba="0 1 0 1"/>
      </material>
    </visual>
    <collision>
      <origin rpy="0 0 0" xyz="0 0.0185 -0.0315"/>
      <geometry>
        <box size="0.122 0.078 0.01"/>
      </geometry>
    </collision>
    <inertial>
      <origin rpy="0 0 0" xyz="0 0.0185 -0.0315"/>
      <mass value="0.02346"/>
      <inertia ixx="2.929372e-05" ixy="0" ixz="0" iyy="4.099244e-05" iyz="0" izz="1.208972e-05"/>
    </inertial>
  </link>
  <joint name="Lfsensor1_joint" type="fixed">
    <origin rpy="0 0 0" xyz="0 0 -0.0365"/>
    <parent link="Lfoot"/>
    <child link="Lfsensor1"/>
  </joint>
  <link name="Lfsensor1">
 		</link>
  <sensor name="Lfsensor1_sensor" update_rate="20">
    <origin rpy="0 0 0" xyz="0 0 -0.0365"/>
    <parent link="Lfoot"/>
  </sensor>
  <gazebo reference="Lhips">
    <selfCollide>false</selfCollide>
    <mu1 value="0.8"/>
    <mu2 value="0.8"/>
    <material>Gazebo/Green</material>
  </gazebo>
  <gazebo reference="Lthigh">
    <selfCollide>false</selfCollide>
    <mu1 value="0.8"/>
    <mu2 value="0.8"/>
    <material>Gazebo/Green</material>
  </gazebo>
  <gazebo reference="Lknee">
    <selfCollide>false</selfCollide>
    <mu1 value="0.8"/>
    <mu2 value="0.8"/>
    <material>Gazebo/Green</material>
  </gazebo>
  <gazebo reference="Lshin">
    <selfCollide>false</selfCollide>
    <mu1 value="0.8"/>
    <mu2 value="0.8"/>
    <material>Gazebo/Green</material>
  </gazebo>
  <gazebo reference="Lankle">
    <selfCollide>false</selfCollide>
    <mu1 value="0.8"/>
    <mu2 value="0.8"/>
    <material>Gazebo/Green</material>
  </gazebo>
  <gazebo reference="Lfoot">
    <selfCollide>false</selfCollide>
    <mu1 value="0.8"/>
    <mu2 value="0.8"/>
    <material>Gazebo/Green</material>
  </gazebo>
  <transmission name="body_2_to_Lhips_tran">
    <type>transmission_interface/SimpleTransmission</type>
    <joint name="body_2_to_Lhips">
      <hardwareInterface>EffortJointInterface</hardwareInterface>
    </joint>
    <actuator name="Lleg_motor1">
      <hardwareInterface>EffortJointInterface</hardwareInterface>
      <mechanicalReduction>1</mechanicalReduction>
    </actuator>
  </transmission>
  <transmission name="Lhips_to_Lthigh_tran">
    <type>transmission_interface/SimpleTransmission</type>
    <joint name="Lhips_to_Lthigh">
      <hardwareInterface>EffortJointInterface</hardwareInterface>
    </joint>
    <actuator name="Lleg_motor2">
      <hardwareInterface>EffortJointInterface</hardwareInterface>
      <mechanicalReduction>1</mechanicalReduction>
    </actuator>
  </transmission>
  <transmission name="Lthigh_to_Lknee_tran">
    <type>transmission_interface/SimpleTransmission</type>
    <joint name="Lthigh_to_Lknee">
      <hardwareInterface>EffortJointInterface</hardwareInterface>
    </joint>
    <actuator name="Lleg_motor3">
      <hardwareInterface>EffortJointInterface</hardwareInterface>
      <mechanicalReduction>1</mechanicalReduction>
    </actuator>
  </transmission>
  <transmission name="Lknee_to_Lshin_tran">
    <type>transmission_interface/SimpleTransmission</type>
    <joint name="Lknee_to_Lshin">
      <hardwareInterface>EffortJointInterface</hardwareInterface>
    </joint>
    <actuator name="Lleg_motor4">
      <hardwareInterface>EffortJointInterface</hardwareInterface>
      <mechanicalReduction>1</mechanicalReduction>
    </actuator>
  </transmission>
  <transmission name="Lshin_to_Lankle_tran">
    <type>transmission_interface/SimpleTransmission</type>
    <joint name="Lshin_to_Lankle">
      <hardwareInterface>EffortJointInterface</hardwareInterface>
    </joint>
    <actuator name="Lleg_motor5">
      <hardwareInterface>EffortJointInterface</hardwareInterface>
      <mechanicalReduction>1</mechanicalReduction>
    </actuator>
  </transmission>
  <transmission name="Lankle_to_Lfoot_tran">
    <type>transmission_interface/SimpleTransmission</type>
    <joint name="Lankle_to_Lfoot">
      <hardwareInterface>EffortJointInterface</hardwareInterface>
    </joint>
    <actuator name="Lleg_motor6">
      <hardwareInterface>EffortJointInterface</hardwareInterface>
      <mechanicalReduction>1</mechanicalReduction>
    </actuator>
  </transmission>
  <!-- right leg -->
  <joint name="body_2_to_Rhips" type="revolute">
    <parent link="body_2"/>
    <child link="Rhips"/>
    <origin rpy="0 0 0" xyz="0 -0.03 -0.0255"/>
    <axis xyz="0 0 1"/>
    <dynamics damping="0.5"/>
    <limit effort="0.5" lower="-0.785398185" upper="0.52359879" velocity="6.0"/>
  </joint>
  <link name="Rhips">
    <visual>
      <origin rpy="0 0 0" xyz="0 0 0"/>
      <geometry>
        <box size="0.03 0.03 0.0039"/>
      </geometry>
      <material name="green">
        <color rgba="0 1 0 1"/>
      </material>
    </visual>
    <collision>
      <origin rpy="0 0 0" xyz="0 0 0"/>
      <geometry>
        <box size="0.03 0.03 0.0039"/>
      </geometry>
    </collision>
    <inertial>
      <origin rpy="0 0 0" xyz="0 0 0"/>
      <mass value="0.03944"/>
      <inertia ixx="3.0079902e-06" ixy="0" ixz="0" iyy="5.916e-06" iyz="0" izz="3.0079902e-06"/>
    </inertial>
  </link>
  <joint name="Rhips_to_Rthigh" type="revolute">
    <parent link="Rhips"/>
    <child link="Rthigh"/>
    <origin rpy="0 0 0" xyz="0 0 -0.030"/>
    <axis xyz="1 0 0"/>
    <dynamics damping="0.5"/>
    <limit effort="0.5" lower="-0.785398185" upper="0.52359879" velocity="6.0"/>
  </joint>
  <link name="Rthigh">
    <visual>
      <origin rpy="0 0 0" xyz="0 0 0"/>
      <geometry>
        <box size="0.03 0.03 0.026"/>
      </geometry>
      <material name="green">
        <color rgba="0 1 0 1"/>
      </material>
    </visual>
    <collision>
      <origin rpy="0 0 0" xyz="0 0 0"/>
      <geometry>
        <box size="0.03 0.03 0.026"/>
      </geometry>
    </collision>
    <inertial>
      <origin rpy="0 0 0" xyz="0 0 0"/>
      <mass value="0.03944"/>
      <inertia ixx="5.17978666667e-06" ixy="0" ixz="0" iyy="5.916e-06" iyz="0" izz="5.17978666667e-06"/>
    </inertial>
  </link>
  <joint name="Rthigh_to_Rknee" type="revolute">
    <parent link="Rthigh"/>
    <child link="Rknee"/>
    <origin rpy="0 0 0" xyz="0 0 -0.046"/>
    <axis xyz="0 1 0"/>
    <dynamics damping="0.5"/>
    <limit effort="0.5" lower="-2.09439516" upper="0.785398185" velocity="6.0"/>
  </joint>
  <link name="Rknee">
    <visual>
      <origin rpy="0 0 0" xyz="0 0 -0.034"/>
      <geometry>
        <box size="0.03 0.03 0.088"/>
      </geometry>
      <material name="green">
        <color rgba="0 1 0 1"/>
      </material>
    </visual>
    <collision>
      <origin rpy="0 0 0" xyz="0 0 -0.034"/>
      <geometry>
        <box size="0.03 0.03 0.088"/>
      </geometry>
    </collision>
    <inertial>
      <origin rpy="0 0 0" xyz="0 0 -0.034"/>
      <mass value="0.11832"/>
      <inertia ixx="8.522984e-05" ixy="0" ixz="0" iyy="1.7748e-05" iyz="0" izz="8.522984e-05"/>
    </inertial>
  </link>
  <joint name="Rknee_to_Rshin" type="revolute">
    <parent link="Rknee"/>
    <child link="Rshin"/>
    <origin rpy="0 0 0" xyz="-0.0205 0 -0.0885"/>
    <axis xyz="0 1 0"/>
    <dynamics damping="0.5"/>
    <limit effort="0.5" lower="-0.0" upper="2.61799395" velocity="6.0"/>
  </joint>
  <link name="Rshin">
    <visual>
      <origin rpy="0 0 0" xyz="0.0205 0 -0.024"/>
      <geometry>
        <box size="0.03 0.03 0.047"/>
      </geometry>
      <material name="green">
        <color rgba="0 1 0 1"/>
      </material>
    </visual>
    <collision>
      <origin rpy="0 0 0" xyz="0.0205 0 -0.024"/>
      <geometry>
        <box size="0.03 0.03 0.047"/>
      </geometry>
    </collision>
    <inertial>
      <origin rpy="0 0 0" xyz="0.0205 0 -0.024"/>
      <mass value="0.04692"/>
      <inertia ixx="1.215619e-05" ixy="0" ixz="0" iyy="7.038e-06" iyz="0" izz="1.215619e-05"/>
    </inertial>
  </link>
  <joint name="Rshin_to_Rankle" type="revolute">
    <parent link="Rshin"/>
    <child link="Rankle"/>
    <origin rpy="0 0 0" xyz="0.0205 0 -0.0319"/>
    <axis xyz="0 1 0"/>
    <dynamics damping="0.5"/>
    <limit effort="0.5" lower="-1.57079637" upper="1.04719758" velocity="6.0"/>
  </joint>
  <link name="Rankle">
    <visual>
      <origin rpy="0 0 0" xyz="0 0 -0.037"/>
      <geometry>
        <box size="0.03 0.03 0.02"/>
      </geometry>
      <material name="green">
        <color rgba="0 1 0 1"/>
      </material>
    </visual>
    <collision>
      <origin rpy="0 0 0" xyz="0 0 -0.037"/>
      <geometry>
        <box size="0.03 0.03 0.02"/>
      </geometry>
    </collision>
    <inertial>
      <origin rpy="0 0 0" xyz="0 0 -0.037"/>
      <mass value="0.04692"/>
      <inertia ixx="5.083e-06" ixy="0" ixz="0" iyy="7.038e-06" iyz="0" izz="5.083e-06"/>
    </inertial>
  </link>
  <joint name="Rankle_to_Rfoot" type="revolute">
    <parent link="Rankle"/>
    <child link="Rfoot"/>
    <origin rpy="0 0 0" xyz="0 0 -0.037"/>
    <axis xyz="1 0 0"/>
    <dynamics damping="0.5"/>
    <limit effort="0.5" lower="-0.785398185" upper="0.785398185" velocity="6.0"/>
  </joint>
  <link name="Rfoot">
    <visual>
      <origin rpy="0 0 0" xyz="0 -0.0185 -0.0315"/>
      <geometry>
        <box size="0.122 0.078 0.01"/>
      </geometry>
      <material name="green">
        <color rgba="0 1 0 1"/>
      </material>
    </visual>
    <collision>
      <origin rpy="0 0 0" xyz="0 -0.0185 -0.0315"/>
      <geometry>
        <box size="0.122 0.078 0.01"/>
      </geometry>
    </collision>
    <inertial>
      <origin rpy="0 0 0" xyz="0 -0.0185 -0.0315"/>
      <mass value="0.02346"/>
      <inertia ixx="2.929372e-05" ixy="0" ixz="0" iyy="4.099244e-05" iyz="0" izz="1.208972e-05"/>
    </inertial>
  </link>
  <joint name="Rfsensor1_joint" type="fixed">
    <origin rpy="0 0 0" xyz="0 0 -0.0365"/>
    <parent link="Rfoot"/>
    <child link="Rfsensor1"/>
  </joint>
  <link name="Rfsensor1">
 		</link>
  <sensor name="Rfsensor1_sensor" update_rate="20">
    <origin rpy="0 0 0" xyz="0 0 -0.0365"/>
    <parent link="Rfoot"/>
  </sensor>
  <gazebo reference="Rhips">
    <selfCollide>false</selfCollide>
    <mu1 value="0.8"/>
    <mu2 value="0.8"/>
    <material>Gazebo/Green</material>
  </gazebo>
  <gazebo reference="Rthigh">
    <selfCollide>false</selfCollide>
    <mu1 value="0.8"/>
    <mu2 value="0.8"/>
    <material>Gazebo/Green</material>
  </gazebo>
  <gazebo reference="Rknee">
    <selfCollide>false</selfCollide>
    <mu1 value="0.8"/>
    <mu2 value="0.8"/>
    <material>Gazebo/Green</material>
  </gazebo>
  <gazebo reference="Rshin">
    <selfCollide>false</selfCollide>
    <mu1 value="0.8"/>
    <mu2 value="0.8"/>
    <material>Gazebo/Green</material>
  </gazebo>
  <gazebo reference="Rankle">
    <selfCollide>false</selfCollide>
    <mu1 value="0.8"/>
    <mu2 value="0.8"/>
    <material>Gazebo/Green</material>
  </gazebo>
  <gazebo reference="Rfoot">
    <selfCollide>false</selfCollide>
    <mu1 value="0.8"/>
    <mu2 value="0.8"/>
    <material>Gazebo/Green</material>
  </gazebo>
  <transmission name="body_2_to_Rhips_tran">
    <type>transmission_interface/SimpleTransmission</type>
    <joint name="body_2_to_Rhips">
      <hardwareInterface>EffortJointInterface</hardwareInterface>
    </joint>
    <actuator name="Rleg_motor1">
      <hardwareInterface>EffortJointInterface</hardwareInterface>
      <mechanicalReduction>1</mechanicalReduction>
    </actuator>
  </transmission>
  <transmission name="Rhips_to_Rthigh_tran">
    <type>transmission_interface/SimpleTransmission</type>
    <joint name="Rhips_to_Rthigh">
      <hardwareInterface>EffortJointInterface</hardwareInterface>
    </joint>
    <actuator name="Rleg_motor2">
      <hardwareInterface>EffortJointInterface</hardwareInterface>
      <mechanicalReduction>1</mechanicalReduction>
    </actuator>
  </transmission>
  <transmission name="Rthigh_to_Rknee_tran">
    <type>transmission_interface/SimpleTransmission</type>
    <joint name="Rthigh_to_Rknee">
      <hardwareInterface>EffortJointInterface</hardwareInterface>
    </joint>
    <actuator name="Rleg_motor3">
      <hardwareInterface>EffortJointInterface</hardwareInterface>
      <mechanicalReduction>1</mechanicalReduction>
    </actuator>
  </transmission>
  <transmission name="Rknee_to_Rshin_tran">
    <type>transmission_interface/SimpleTransmission</type>
    <joint name="Rknee_to_Rshin">
      <hardwareInterface>EffortJointInterface</hardwareInterface>
    </joint>
    <actuator name="Rleg_motor4">
      <hardwareInterface>EffortJointInterface</hardwareInterface>
      <mechanicalReduction>1</mechanicalReduction>
    </actuator>
  </transmission>
  <transmission name="Rshin_to_Rankle_tran">
    <type>transmission_interface/SimpleTransmission</type>
    <joint name="Rshin_to_Rankle">
      <hardwareInterface>EffortJointInterface</hardwareInterface>
    </joint>
    <actuator name="Rleg_motor5">
      <hardwareInterface>EffortJointInterface</hardwareInterface>
      <mechanicalReduction>1</mechanicalReduction>
    </actuator>
  </transmission>
  <transmission name="Rankle_to_Rfoot_tran">
    <type>transmission_interface/SimpleTransmission</type>
    <joint name="Rankle_to_Rfoot">
      <hardwareInterface>EffortJointInterface</hardwareInterface>
    </joint>
    <actuator name="Rleg_motor6">
      <hardwareInterface>EffortJointInterface</hardwareInterface>
      <mechanicalReduction>1</mechanicalReduction>
    </actuator>
  </transmission>
</robot>

>>>>>>> 42ca683593df3d34624e90336fab16e0fade033c
