<<<<<<< HEAD
<?xml version="1.0"?>
<robot name="robot">

 <link name="base_link">
  <visual>
   <origin xyz="0 0 0.025" rpy="0 0 0"/>
   <geometry>
    <box size="0.05 0.05 0.05"/>
   </geometry>
   <material name="blue">
    <color rgba="0 0 1 1"/>
   </material>
  </visual>
 </link>

 <link name="link1">
  <visual>
   <origin xyz="0 0 0.025" rpy="0 0 0"/>
   <geometry>
    <box size="0.05 0.05 0.05"/>
   </geometry>
   <material name="blue"/>
  </visual>
 </link>

 <joint name="joint1" type="revolute">
  <parent link="base_link"/>
  <child link="link1"/>
  <origin xyz="0 0 0.05" rpy="0 0 0"/>
  <axis xyz="0 1 0"/>
  <limit lower="-1.57" upper="1.57" effort="0.5293" velocity="6.159937255" />
  <friction friction="0.01" />
  <dynamics damping="0.4" />
 </joint>

 <joint name="joint2" type="revolute">
  <parent link="base_link"/>
  <child link="link1"/>
  <axis xyz="1 0 0"/>
  <origin xyz="0 0 0.05" rpy="0 0 0"/>
  <limit lower="-1.57" upper="1.57" effort="0.5293" velocity="6.159937255" />
  </joint>
 
</robot>
=======
<?xml version="1.0"?>
<robot name="robot">

 <link name="base_link">
  <visual>
   <origin xyz="0 0 0.025" rpy="0 0 0"/>
   <geometry>
    <box size="0.05 0.05 0.05"/>
   </geometry>
   <material name="blue">
    <color rgba="0 0 1 1"/>
   </material>
  </visual>
 </link>

 <link name="link1">
  <visual>
   <origin xyz="0 0 0.025" rpy="0 0 0"/>
   <geometry>
    <box size="0.05 0.05 0.05"/>
   </geometry>
   <material name="blue"/>
  </visual>
 </link>

 <joint name="joint1" type="revolute">
  <parent link="base_link"/>
  <child link="link1"/>
  <origin xyz="0 0 0.05" rpy="0 0 0"/>
  <axis xyz="0 1 0"/>
  <limit lower="-1.57" upper="1.57" effort="0.5293" velocity="6.159937255" />
  <friction friction="0.01" />
  <dynamics damping="0.4" />
 </joint>

 <joint name="joint2" type="revolute">
  <parent link="base_link"/>
  <child link="link1"/>
  <axis xyz="1 0 0"/>
  <origin xyz="0 0 0.05" rpy="0 0 0"/>
  <limit lower="-1.57" upper="1.57" effort="0.5293" velocity="6.159937255" />
  </joint>
 
</robot>
>>>>>>> 42ca683593df3d34624e90336fab16e0fade033c
