<?xml version="1.0"?>
<robot xmlns:xacro="http://ros.org/wiki/xacro">

<xacro:include filename="$(find sotuken2017)/urdf/common.xacro"/>
	
  <property name="ef" value="1.37293"/>
  <property name="vel" value="0.14"/>
	
  <property name="arm_xy" value="0.026"/>
  
  <property name="shoulder_z" value="0.036"/>
  <property name="shoulder_mass" value="0.0625"/>
  
  <property name="upper_arm_z" value="0.082"/>
  <property name="upper_arm_mass" value="0.0625"/>
  
  <property name="lower_arm_z" value="0.056"/>
  <property name="lower_arm_mass" value="0.025"/>
  
 <xacro:macro name="make_arm" params="parent LRarm ref arm_bool">
     <joint name="${parent}_to_${LRarm}shoulder" type="revolute">
        <parent link="${parent}"/>
        <child link="${LRarm}shoulder"/>
        <origin xyz="0 ${ref * 0.0525} 0.018" rpy="0 0 0"/>
        <axis xyz="0 1 0"/>
		<dynamics damping="0.5"/>
        <limit lower="-${M_PI}" upper="${M_PI / 3}" effort="${ef}" velocity="${vel}"/>
     </joint>

     <link name="${LRarm}shoulder">
        <visual>
            <origin xyz="0 ${ref * 0.023} 0" rpy="0 0 0"/>
            <geometry>
                <box size="${arm_xy} ${arm_xy} ${shoulder_z}"/>
            </geometry>
            <xacro:darkgray/>
        </visual>

        <collision>
            <origin xyz="0 ${ref * 0.023} 0" rpy="0 0 0"/>
            <geometry>
                <box size="${arm_xy} ${arm_xy} ${shoulder_z}"/>
            </geometry>
        </collision>

        <inertial>
           <origin xyz="0 ${ref * 0.023} 0" rpy="0 0 0"/>
           <xacro:box_inertial m="${shoulder_mass}" d="${arm_xy}" w="${arm_xy}" h="${shoulder_z}"/>
        </inertial>
     </link>

     <joint name="${LRarm}shoulder_to_${LRarm}upper_arm" type="revolute">
        <parent link="${LRarm}shoulder"/>
        <child link="${LRarm}upper_arm"/>
        <origin xyz="0 ${ref * 0.023} 0" rpy="0 0 0"/>
        <axis xyz="1 0 0"/>
		<dynamics damping="0.5"/>
        <xacro:if value="${arm_bool}">
            <limit lower="-0.0" upper="${M_PI / 2}" effort="${ef}" velocity="${vel}"/>
        </xacro:if>
		<xacro:unless value="${arm_bool}">
			<limit lower="-${M_PI / 2}" upper="0.0" effort="${ef}" velocity="${vel}"/>
		</xacro:unless>
     </joint>

     <link name="${LRarm}upper_arm">
        <visual>
            <origin xyz="0 0 -0.079" rpy="0 0 0"/>
            <geometry>
                <box size="${arm_xy} ${arm_xy} ${upper_arm_z}"/>
            </geometry>
            <xacro:darkgray/>
        </visual>

        <collision>
            <origin xyz="0 0 -0.079" rpy="0 0 0"/>
            <geometry>
                <box size="${arm_xy} ${arm_xy} ${upper_arm_z}"/>
            </geometry>
        </collision>

        <inertial>
            <origin xyz="0 0 -0.079" rpy="0 0 0"/>
            <xacro:box_inertial m="${upper_arm_mass}" d="${arm_xy}" w="${arm_xy}" h="${upper_arm_z}"/>
        </inertial>
    </link>

    <joint name="${LRarm}upper_arm_to_${LRarm}lower_arm" type="revolute">
        <parent link="${LRarm}upper_arm"/>
        <child link="${LRarm}lower_arm"/>
        <origin xyz="${arm_xy / 2} 0 -0.125" rpy="0 0 0"/>
        <axis xyz="0 1 0"/>
		<dynamics damping="0.5"/>
        <limit lower="-${M_PI * 5 / 6}" upper="0.0" effort="${ef}" velocity="${vel}"/>
    </joint>

    <link name="${LRarm}lower_arm">
        <visual>
            <origin xyz="-${arm_xy / 2} 0 -0.033" rpy="0 0 0"/>
            <geometry>
                <box size="${arm_xy} ${arm_xy} ${lower_arm_z}"/>
            </geometry>
            <xacro:darkgray/>
        </visual>

        <collision>
            <origin xyz="-${arm_xy / 2} 0 -0.033" rpy="0 0 0"/>
            <geometry>
                <box size="${arm_xy} ${arm_xy} ${lower_arm_z}"/>
            </geometry>
        </collision>

        <inertial>
            <origin xyz="-${arm_xy / 2} 0 -0.033" rpy="0 0 0"/>
            <xacro:box_inertial m="${lower_arm_mass}" d="${arm_xy}" w="${arm_xy}" h="${lower_arm_z}"/>
        </inertial>
    </link>
	 
  </xacro:macro>

</robot>
